Workbook

Sheet 予選
A1: サンプル
J2: 日程 | M2: ： | O2: 令和７年９月23日（祝）予備日９月３０日（土）
J3: 会場 | M3: ： | O3: ヤマタスポーツパークテニスコート 予備日：千代コート
F5: （１） 予選・決勝共ノーアドバンテージ・６ゲームマッチ（６-６タイブレーク） ※5チームリーグ別記
F6: （２） 予選リーグ試合順… | N6: ①-② ③-④ ①-③ ②-④ ①-④ ②-③ ※5チームリーグ別記
F7: （３） リーグ戦の順位決定方法 | P7: 勝率が同じペアが２つのとき：対戦勝者が上位
P8: 勝率が同じペアが３つのとき：取得ゲーム率が高いペアが上位とします。
F9: （４） 各リーグの2番目のペアに、そのリーグの進行管理をお願いします。
F10: （５） 大会当日の棄権があった場合、予選リーグの試合方式を変更する場合があります。
F11: （６） 雨天の場合の問い合わせ先 鳥取市テニス協会 080-1354-0278
F12: （７） ペア変更については期日までに連絡を頂ければ許可致します。（両ペア変更不可・市登録者に限る）
B13: 連絡先・締切 ９月21日(日) FAX 0857-59-1837のみで受付
B14: ■予選リーグ | P14: AM8:00 開場、AM8:45 受付終了、AM9:00 試合開始2 6ゲームマッチ（6-6ﾀｲﾌﾞﾚｰｸ・ﾉｰｱﾄﾞﾊﾞﾝﾃｰｼﾞ）
B15: Aリーグ | G15: 1 | H15: 藤田 智博 | K15: Love ALL | O15: 2 | P15: 岸本 健悟 | S15: オレンジ | W15: 3 | X15: 西山 禎侑 | AA15: ｄｏＭｅ | AE15: 4 | AF15: 三宅 諒弥 | AI15: 鳥取銀行
B16: 1コート | H16: 山根 陽子 | K16: フリー | P16: 三浦 舞子 | S16: サニーＴＳ | X16: 小林 さえ子 | AA16: カプリス | AF16: 山本 桂 | AI16: たんぽぽ
B17: Bリーグ | G17: 5 | H17: 常村 和仁 | K17: 完熟オレンジ | O17: 6 | P17: 山辺 裕司 | S17: ｄｏＭｅ | W17: 7 | X17: 高垣 護 | AA17: Drop☆Shot | AE17: 8 | AF17: 津田 智広 | AI17: ノーレット７
B18: ２コート | H18: 前田 良枝 | K18: Ｚｏｎｅ | P18: 蓼本 裕美 | S18: ｄｏＭｅ | X18: 門脇 春美 | AA18: あみたま | AF18: 米谷 さおり | AI18: フリー
B19: Cリーグ | G19: 9 | H19: 近藤 哲生 | K19: 因幡打輪 | O19: 10 | P19: 林原 政幸 | S19: フリー | W19: 11 | X19: 和気 久 | AA19: ＢＳＣ | AE19: 12 | AF19: 山下 悠樹 | AI19: ｏｆｆ
B20: ３コート | H20: 前田 陽子 | K20: フリー | P20: 林原 史子 | S20: フリー | X20: 長川 朱美 | AA20: ロランギャロス | AF20: 田苗 真里 | AI20: フリー
B21: Dリーグ | G21: 13 | H21: 小谷 桂介 | K21: Ｔ-nuts | O21: 14 | P21: 中里 海 | S21: 湖山池ＴＣ | W21: 15 | X21: 網川 忠之 | AA21: フリー | AE21: 16 | AF21: 羽馬 由和 | AI21: オレンジ
B22: ４コート | H22: 小谷 佐知子 | K22: Ｔ-nuts | P22: 市川 朋子 | S22: あみたま | X22: 網川佐知子 | AA22: フリー | AF22: 杉原 三奈 | AI22: ジュピター
B23: Eリーグ | G23: 17 | H23: 谷本 卓也 | K23: ｄｏＭｅ | O23: 18 | P23: 田中 憲一 | S23: ポップテニスプラス | W23: 19 | X23: 椿 誠 | AA23: フリー | AE23: 20 | AF23: 町田 正雄 | AI23: 因幡打輪
B24: ５コート | H24: 谷口 圭子 | K24: レイリー | P24: 山﨑 弥生 | S24: 鳥取銀行 | X24: 椿 保奈瀬 | AA24: フリー | AF24: 町田 聖子 | AI24: 因幡打輪
B25: Fリーグ | G25: 21 | H25: 杉野 隆志 | K25: アスペック | O25: 22 | P25: 小谷神一郎 | S25: フリー | W25: 23 | X25: 朝倉章順 | AA25: ロランギャロス | AE25: 24 | AF25: 山本 和弥 | AI25: オレンジ
B26: ６･7コート | H26: 中村 公恵 | K26: 田園 | P26: 青木 楓 | S26: フリー | X26: 朝倉加世子 | AA26: ロランギャロス | AF26: 濱田 久美 | AI26: フリー
B27: Gリーグ | G27: 25 | H27: 米村 琢巳 | K27: フリー | O27: 26 | P27: 松原 成哉 | S27: ｄｏＭｅ | W27: 27 | X27: 田中 達也 | AA27: たんぽぽ | AE27: 28 | AF27: 中村 匡延 | AI27: プラセール
B28: 8コート | H28: 佐藤 陽子 | K28: ウィード | P28: 宮島 依吹 | S28: ｄｏＭｅ | X28: 田渕 夕起子 | AA28: ポップテニスプラス | AF28: 伊吹 優子 | AI28: ノーレット７
B29: Hリーグ | G29: 29 | H29: 小川 拓 | K29: プラセール | O29: 30 | P29: 坪上 雄太 | S29: メテオスマッシュ | W29: 31 | X29: 砂原 翔 | AA29: ｏｆｆ | AE29: 32 | AF29: 外園 真都 | AI29: 鳥取環境大
B30: 9コート | H30: 山内 恵子 | K30: プラセール | P30: 高垣 雅美 | S30: レイリー | X30: 藤田登紀子 | AA30: フリー | AF30: 船越 海希 | AI30: 鳥取環境大
B31: I リーグ | G31: 33 | H31: 山口 辰之 | K31: サニーＴＳ | O31: 34 | P31: 高木 道大 | S31: 因幡打輪 | W31: 35 | X31: 橋本 真也 | AA31: Drop☆Shot | AE31: 36 | AF31: 西口 幸雄 | AI31: プラセール
B32: 10コート | H32: 宮本 真有 | K32: デネブ | P32: 北脇 禎恵 | S32: フリー | X32: 馬嶋由美子 | AA32: フリー | AF32: 西口 栄子 | AI32: プラセール
B33: Jリーグ | G33: 37 | H33: 細川 善貴 | K33: ｄｏＭｅ | O33: 38 | P33: 柳武 剛 | S33: Vivace | W33: 39 | X33: 盛本 貴之 | AA33: カプリス | AE33: 40 | AF33: 高木 克憲 | AI33: ｏｆｆ
B34: 11コート | H34: 厨子沙也香 | K34: フリー | P34: 鳥飼 明子 | S34: フリー | X34: 仲曽真由美 | AA34: BSC | AF34: 田中 好美 | AI34: あみたま
B35: Kリーグ | G35: 41 | H35: 丸川 康生 | K35: 因幡打輪 | O35: 42 | P35: 田中 久夫 | S35: カプリス | W35: 43 | X35: 難波 隆顕 | AA35: プラセール | AE35: 44 | AF35: 檜垣 直斗 | AI35: フリー
B36: 12コート | H36: 山根 崇子 | K36: フリー | P36: 林 京子 | S36: フリー | X36: 森 順子 | AA36: フリー | AF36: 橋本 舞子 | AI36: スポーツショップハート
G37: 45 | H37: 小椋 浩二 | K37: てーくおふ | O37: 46 | P37: 住吉 俊輝 | S37: プラセール | W37: 47 | X37: 吉田 浩士 | AA37: ノーレット７ | AE37: 48 | AF37: 藤田 和幸 | AI37: フリー
B38: Lリーグ | H38: 前田美由紀 | K38: てーくおふ | P38: 福浜美佐緒 | S38: プラセール | X38: 岡田 友子 | AA38: ノーレット７ | AF38: 藤田 美和 | AI38: フリー
B39: 13･14コート | G39: 49 | H39: 清水 貴志 | K39: フリー | O39: ■６ゲーム先取（ノーアドバンテージ） ■試合順：①-② ③-④ ①-⑤ ②-③ ①-④ ②-⑤ ③-⑤ ②-④ ④-⑤ ①-③ ■49番のペアの方は4チームリーグに欠場が出た場合、移動して頂く場合が有ります。
H40: 大田 陽子 | K40: たんぽぽ
G41: 50 | H41: 竹安 秀平 | K41: ＲｅＦｌｅｘ | O41: 51 | P41: 橋本 義斉 | S41: Drop☆Shot | W41: 52 | X41: 井嶋 昭二 | AA41: RedHotChiliPeppers | AE41: 53 | AF41: 吉田 拳士 | AI41: サニーテニス
...

Sheet リスト
A1: リーグ | B1: 番号 | C1: 名前 | D1: 所属 | E1: リーグ*順位 | F1: 番号 | G1: 順位
A2: A | B2: 1-1 | C2: 藤田 智博 | D2: Love ALL | E2: =A2&G2 -> A1 | F2: =LEFT(B2, FIND("-", B2) - 1) -> 1 | G2: =LEFT(VLOOKUP(VALUE(F2),'予選L結果'!$B$4:$L$165,11, FALSE),1) -> 1
A3: A | B3: 1-2 | C3: 山根 陽子 | D3: フリー | E3: =A3&G3 -> A1 | F3: =LEFT(B3, FIND("-", B3) - 1) -> 1 | G3: =LEFT(VLOOKUP(VALUE(F3),'予選L結果'!$B$4:$L$165,11, FALSE),1) -> 1
A4: A | B4: 2-1 | C4: 岸本 健悟 | D4: オレンジ | E4: =A4&G4 -> A2 | F4: =LEFT(B4, FIND("-", B4) - 1) -> 2 | G4: =LEFT(VLOOKUP(VALUE(F4),'予選L結果'!$B$4:$L$165,11, FALSE),1) -> 2
A5: A | B5: 2-2 | C5: 三浦 舞子 | D5: サニーＴＳ | E5: =A5&G5 -> A2 | F5: =LEFT(B5, FIND("-", B5) - 1) -> 2 | G5: =LEFT(VLOOKUP(VALUE(F5),'予選L結果'!$B$4:$L$165,11, FALSE),1) -> 2
A6: A | B6: 3-1 | C6: 西山 禎侑 | D6: ｄｏＭｅ | E6: =A6&G6 -> A3 | F6: =LEFT(B6, FIND("-", B6) - 1) -> 3 | G6: =LEFT(VLOOKUP(VALUE(F6),'予選L結果'!$B$4:$L$165,11, FALSE),1) -> 3
A7: A | B7: 3-2 | C7: 小林 さえ子 | D7: カプリス | E7: =A7&G7 -> A3 | F7: =LEFT(B7, FIND("-", B7) - 1) -> 3 | G7: =LEFT(VLOOKUP(VALUE(F7),'予選L結果'!$B$4:$L$165,11, FALSE),1) -> 3
A8: A | B8: 4-1 | C8: 三宅 諒弥 | D8: 鳥取銀行 | E8: =A8&G8 -> A4 | F8: =LEFT(B8, FIND("-", B8) - 1) -> 4 | G8: =LEFT(VLOOKUP(VALUE(F8),'予選L結果'!$B$4:$L$165,11, FALSE),1) -> 4
A9: A | B9: 4-2 | C9: 山本 桂 | D9: たんぽぽ | E9: =A9&G9 -> A4 | F9: =LEFT(B9, FIND("-", B9) - 1) -> 4 | G9: =LEFT(VLOOKUP(VALUE(F9),'予選L結果'!$B$4:$L$165,11, FALSE),1) -> 4
A10: B | B10: 5-1 | C10: 常村 和仁 | D10: 完熟オレンジ | E10: =A10&G10 -> B1 | F10: =LEFT(B10, FIND("-", B10) - 1) -> 5 | G10: =LEFT(VLOOKUP(VALUE(F10),'予選L結果'!$B$4:$L$165,11, FALSE),1) -> 1
A11: B | B11: 5-2 | C11: 前田 良枝 | D11: Ｚｏｎｅ | E11: =A11&G11 -> B1 | F11: =LEFT(B11, FIND("-", B11) - 1) -> 5 | G11: =LEFT(VLOOKUP(VALUE(F11),'予選L結果'!$B$4:$L$165,11, FALSE),1) -> 1
A12: B | B12: 6-1 | C12: 山辺 裕司 | D12: ｄｏＭｅ | E12: =A12&G12 -> B2 | F12: =LEFT(B12, FIND("-", B12) - 1) -> 6 | G12: =LEFT(VLOOKUP(VALUE(F12),'予選L結果'!$B$4:$L$165,11, FALSE),1) -> 2
A13: B | B13: 6-2 | C13: 蓼本 裕美 | D13: ｄｏＭｅ | E13: =A13&G13 -> B2 | F13: =LEFT(B13, FIND("-", B13) - 1) -> 6 | G13: =LEFT(VLOOKUP(VALUE(F13),'予選L結果'!$B$4:$L$165,11, FALSE),1) -> 2
... A89: K | B89: 44-2 | C89: 橋本 舞子 | D89: スポーツショップハート | E89: =A89&G89 -> K4 | F89: =LEFT(B89, FIND("-", B89) - 1) -> 44 | G89: =LEFT(VLOOKUP(VALUE(F89),'予選L結果'!$B$4:$L$165,11, FALSE),1) -> 4
A90: L | B90: 45-1 | C90: 小椋 浩二 | D90: てーくおふ | E90: =A90&G90 -> L1 | F90: =LEFT(B90, FIND("-", B90) - 1) -> 45 | G90: =LEFT(VLOOKUP(VALUE(F90),'予選L結果(2)'!$B$4:$M$36,12, FALSE),1) -> 1
A91: L | B91: 45-2 | C91: 前田 美由紀 | D91: てーくおふ | E91: =A91&G91 -> L1 | F91: =LEFT(B91, FIND("-", B91) - 1) -> 45 | G91: =LEFT(VLOOKUP(VALUE(F91),'予選L結果(2)'!$B$4:$M$36,12, FALSE),1) -> 1
A92: L | B92: 46-1 | C92: 住吉 俊輝 | D92: プラセール | E92: =A92&G92 -> L2 | F92: =LEFT(B92, FIND("-", B92) - 1) -> 46 | G92: =LEFT(VLOOKUP(VALUE(F92),'予選L結果(2)'!$B$4:$M$36,12, FALSE),1) -> 2
A93: L | B93: 46-2 | C93: 福浜 美佐緒 | D93: プラセール | E93: =A93&G93 -> L2 | F93: =LEFT(B93, FIND("-", B93) - 1) -> 46 | G93: =LEFT(VLOOKUP(VALUE(F93),'予選L結果(2)'!$B$4:$M$36,12, FALSE),1) -> 2
A94: L | B94: 47-1 | C94: 吉田 浩士 | D94: ノーレット７ | E94: =A94&G94 -> L3 | F94: =LEFT(B94, FIND("-", B94) - 1) -> 47 | G94: =LEFT(VLOOKUP(VALUE(F94),'予選L結果(2)'!$B$4:$M$36,12, FALSE),1) -> 3
A95: L | B95: 47-2 | C95: 岡田 友子 | D95: ノーレット７ | E95: =A95&G95 -> L3 | F95: =LEFT(B95, FIND("-", B95) - 1) -> 47 | G95: =LEFT(VLOOKUP(VALUE(F95),'予選L結果(2)'!$B$4:$M$36,12, FALSE),1) -> 3
A96: L | B96: 48-1 | C96: 藤田 和幸 | D96: フリー | E96: =A96&G96 -> L4 | F96: =LEFT(B96, FIND("-", B96) - 1) -> 48 | G96: =LEFT(VLOOKUP(VALUE(F96),'予選L結果(2)'!$B$4:$M$36,12, FALSE),1) -> 4
A97: L | B97: 48-2 | C97: 藤田 美和 | D97: フリー | E97: =A97&G97 -> L4 | F97: =LEFT(B97, FIND("-", B97) - 1) -> 48 | G97: =LEFT(VLOOKUP(VALUE(F97),'予選L結果(2)'!$B$4:$M$36,12, FALSE),1) -> 4
A98: L | B98: 49-1 | C98: 清水 貴志 | D98: フリー | E98: =A98&G98 -> L5 | F98: =LEFT(B98, FIND("-", B98) - 1) -> 49 | G98: =LEFT(VLOOKUP(VALUE(F98),'予選L結果(2)'!$B$4:$M$36,12, FALSE),1) -> 5
A99: L | B99: 49-2 | C99: 大田 陽子 | D99: たんぽぽ | E99: =A99&G99 -> L5 | F99: =LEFT(B99, FIND("-", B99) - 1) -> 49 | G99: =LEFT(VLOOKUP(VALUE(F99),'予選L結果(2)'!$B$4:$M$36,12, FALSE),1) -> 5
A100: M | B100: 50-1 | C100: 竹安 秀平 | D100: ＲｅＦｌｅｘ | E100: =A100&G100 -> M1 | F100: =LEFT(B100, FIND("-", B100) - 1) -> 50 | G100: =LEFT(VLOOKUP(VALUE(F100),'予選L結果(2)'!$B$4:$M$36,12, FALSE),1) -> 1
A101: M | B101: 50-2 | C101: 楠瀬 翔子 | D101: アポロＴＣ | E101: =A101&G101 -> M1 | F101: =LEFT(B101, FIND("-", B101) - 1) -> 50 | G101: =LEFT(VLOOKUP(VALUE(F101),'予選L結果(2)'!$B$4:$M$36,12, FALSE),1) -> 1
... A109: M | B109: 54-2 | C109: 遠藤 夏希 | D109: 湖山池ＴＣ | E109: =A109&G109 -> M4 | F109: =LEFT(B109, FIND("-", B109) - 1) -> 54 | G109: =LEFT(VLOOKUP(VALUE(F109),'予選L結果(2)'!$B$4:$M$36,12, FALSE),1) -> 4

Sheet 予選L結果
B2: A | E2: リーグ | I2: =TRIM('予選'!$A$1) -> サンプル
B3: 選手名 | G3: =LEFT(C4, FIND(" ", C4 & " ") - 1) & "・" & LEFT(C6, FIND(" ", C6 & " ") - 1) -> 藤田・山根 | H3: =LEFT(C7, FIND(" ", C7 & " ") - 1) & "・" & LEFT(C9, FIND(" ", C9 & " ") - 1) -> 岸本・三浦 | I3: =LEFT(C10, FIND(" ", C10 & " ") - 1) & "・" & LEFT(C12, FIND(" ", C12 & " ") - 1) -> 西山・小林 | J3: =LEFT(C13, FIND(" ", C13 & " ") - 1) & "・" & LEFT(C15, FIND(" ", C15 & " ") - 1) -> 三宅・山本 | K3: 勝敗 | L3: 順位 | N3: 勝数 | O3: 勝率 | P3: 直接対決 | Q3: 判定 | R3: 順位
B4: 1 | C4: =IFERROR(VLOOKUP(B4&"-"&1,'リスト'!$B:$D,2,FALSE),"") -> 藤田 智博 | F4: =IFERROR(VLOOKUP(B4&"-"&1,'リスト'!$B:$D,3,FALSE),"") -> Love ALL | G4: =IFERROR(__xludf.DUMMYFUNCTION("SPARKLINE({1,0})"),"") | H4: 6-0 | I4: 6-0 | J4: 4-6 | K4: =IFERROR(__xludf.DUMMYFUNCTION("SUMPRODUCT(--(REGEXMATCH(TO_TEXT(G4:J4), ""-"")), IFERROR(--(LEFT(G4:J4,FIND(""-"",G4:J4)-1)>RIGHT(G4:J4,LEN(G4:J4)-FIND(""-"",G4:J4))),0)) & ""-"" & SUMPRODUCT(--(REGEXMATCH(TO_TEXT(G4:J4), ""-"")), IFERROR(--(LEFT(G4:J4,FIND(""-"",G4:J4)-1)<RIGHT(G4:J4,"&"LEN(G4:J4)-FIND(""-"",G4:J4))),0))"),"2-1") -> 2-1 | L4: =IF(COUNTA(G4,G7,G10,G13,H4,H7,H10,H13,I4,I7,I10,I13,J4,J7,J10,J13)=16,R4,"") -> 1位 | N4: =IFERROR(VALUE(LEFT(K4,FIND("-",K4)-1)),-1) -> 2 | O4: =SUMPRODUCT(IFERROR(--(LEFT(G4:J4,FIND("-",G4:J4)-1)),0)) & "/" & (SUMPRODUCT(IFERROR(--(LEFT(G4:J4,FIND("-",G4:J4)-1)),0)) + SUMPRODUCT(IFERROR(--(RIGHT(G4:J4,LEN(G4:J4)-FIND("-",G4:J4))),0))) -> 16/22 | P4: =IF((COUNTIF($N4,N4)+COUNTIF($N7,N4)+COUNTIF($N10,N4)+COUNTIF($N13,N4))=2, IFERROR(IFS(N4=$N7,IF(VALUE(LEFT(H4,FIND("-",H4)-1))>VALUE(RIGHT(H4,LEN(H4)-FIND("-",H4))),1,0), N4=$N10,IF(VALUE(LEFT(I4,FIND("-",I4)-1))>VALUE(RIGHT(I4,LEN(I4)-FIND("-",I4))),1,0), N4=$N13,IF(VALUE(LEFT(J4,FIND("-",J4)-1))>VALUE(RIGHT(J4,LEN(J4)-FIND("-",J4))),1,0)), ""), "") -> 1 | Q4: {=N4+IF(SUMPRODUCT(--({$N4;$N7;$N10;$N13}=N4))=2,P4*0.1,IF(SUMPRODUCT(--({$N4;$N7;$N10;$N13}=N4))>=3,O5*0.01,0))} -> 2.1 | R4: {=_xlfn.RANK.EQ(Q4, {$Q4;$Q7;$Q10;$Q13}) & "位"} -> 1位
O5: =IFERROR( SUMPRODUCT(IFERROR(--(LEFT(G4:J4,FIND("-",G4:J4)-1)),0)) / (SUMPRODUCT(IFERROR(--(LEFT(G4:J4,FIND("-",G4:J4)-1)),0)) + SUMPRODUCT(IFERROR(--(RIGHT(G4:J4,LEN(G4:J4)-FIND("-",G4:J4))),0))) , 0) -> 0.72727273
C6: =IFERROR(VLOOKUP(B4&"-"&2,'リスト'!$B:$D,2,FALSE),"") -> 山根 陽子 | F6: =IFERROR(VLOOKUP(B4&"-"&2,'リスト'!$B:$D,3,FALSE),"") -> フリー
B7: 2 | C7: =IFERROR(VLOOKUP(B7&"-"&1,'リスト'!$B:$D,2,FALSE),"") -> 岸本 健悟 | F7: =IFERROR(VLOOKUP(B7&"-"&1,'リスト'!$B:$D,3,FALSE),"") -> オレンジ | G7: =IFERROR(MID(H4, FIND("-", H4) + 1, 100) & "-" & LEFT(H4, FIND("-", H4) - 1), "") -> 0-6 | H7: =IFERROR(__xludf.DUMMYFUNCTION("SPARKLINE({1,0})"),"") | I7: 6-0 | J7: 6-5 | K7: =IFERROR(__xludf.DUMMYFUNCTION("SUMPRODUCT(--(REGEXMATCH(TO_TEXT(G7:J7), ""-"")), IFERROR(--(LEFT(G7:J7,FIND(""-"",G7:J7)-1)>RIGHT(G7:J7,LEN(G7:J7)-FIND(""-"",G7:J7))),0)) & ""-"" & SUMPRODUCT(--(REGEXMATCH(TO_TEXT(G7:J7), ""-"")), IFERROR(--(LEFT(G7:J7,FIND(""-"",G7:J7)-1)<RIGHT(G7:J7,"&"LEN(G7:J7)-FIND(""-"",G7:J7))),0))"),"2-1") -> 2-1 | L7: =IF(COUNTA(G4,G7,G10,G13,H4,H7,H10,H13,I4,I7,I10,I13,J4,J7,J10,J13)=16,R7,"") -> 2位 | N7: =IFERROR(VALUE(LEFT(K7,FIND("-",K7)-1)),-1) -> 2 | O7: =SUMPRODUCT(IFERROR(--(LEFT(G7:J7,FIND("-",G7:J7)-1)),0)) & "/" & (SUMPRODUCT(IFERROR(--(LEFT(G7:J7,FIND("-",G7:J7)-1)),0)) + SUMPRODUCT(IFERROR(--(RIGHT(G7:J7,LEN(G7:J7)-FIND("-",G7:J7))),0))) -> 12/23 | P7: =IF((COUNTIF($N4,N7)+COUNTIF($N7,N7)+COUNTIF($N10,N7)+COUNTIF($N13,N7))=2, IFERROR(IFS(N7=$N4,IF(VALUE(LEFT(G7,FIND("-",G7)-1))>VALUE(RIGHT(G7,LEN(G7)-FIND("-",G7))),1,0), N7=$N10,IF(VALUE(LEFT(I7,FIND("-",I7)-1))>VALUE(RIGHT(I7,LEN(I7)-FIND("-",I7))),1,0), N7=$N13,IF(VALUE(LEFT(J7,FIND("-",J7)-1))>VALUE(RIGHT(J7,LEN(J7)-FIND("-",J7))),1,0)), ""), "") -> 0 | Q7: {=N7+IF(SUMPRODUCT(--({$N4;$N7;$N10;$N13}=N7))=2,P7*0.1,IF(SUMPRODUCT(--({$N4;$N7;$N10;$N13}=N7))>=3,O8*0.01,0))} -> 2 | R7: {=_xlfn.RANK.EQ(Q7, {$Q4;$Q7;$Q10;$Q13}) & "位"} -> 2位
O8: =IFERROR( SUMPRODUCT(IFERROR(--(LEFT(G7:J7,FIND("-",G7:J7)-1)),0)) / (SUMPRODUCT(IFERROR(--(LEFT(G7:J7,FIND("-",G7:J7)-1)),0)) + SUMPRODUCT(IFERROR(--(RIGHT(G7:J7,LEN(G7:J7)-FIND("-",G7:J7))),0))) , 0) -> 0.52173913
C9: =IFERROR(VLOOKUP(B7&"-"&2,'リスト'!$B:$D,2,FALSE),"") -> 三浦 舞子 | F9: =IFERROR(VLOOKUP(B7&"-"&2,'リスト'!$B:$D,3,FALSE),"") -> サニーＴＳ
B10: 3 | C10: =IFERROR(VLOOKUP(B10&"-"&1,'リスト'!$B:$D,2,FALSE),"") -> 西山 禎侑 | F10: =IFERROR(VLOOKUP(B10&"-"&1,'リスト'!$B:$D,3,FALSE),"") -> ｄｏＭｅ | G10: =IFERROR(MID(I4, FIND("-", I4) + 1, 100) & "-" & LEFT(I4, FIND("-", I4) - 1), "") -> 0-6 | H10: =IFERROR(MID(I7, FIND("-", I7) + 1, 100) & "-" & LEFT(I7, FIND("-", I7) - 1), "") -> 0-6 | I10: =IFERROR(__xludf.DUMMYFUNCTION("SPARKLINE({1,0})"),"") | J10: 6-2 | K10: =IFERROR(__xludf.DUMMYFUNCTION("SUMPRODUCT(--(REGEXMATCH(TO_TEXT(G10:J10), ""-"")), IFERROR(--(LEFT(G10:J10,FIND(""-"",G10:J10)-1)>RIGHT(G10:J10,LEN(G10:J10)-FIND(""-"",G10:J10))),0)) & ""-"" & SUMPRODUCT(--(REGEXMATCH(TO_TEXT(G10:J10), ""-"")), IFERROR(--(LEFT(G10:J10,FIND(""-"",G10:J1"&"0)-1)<RIGHT(G10:J10,LEN(G10:J10)-FIND(""-"",G10:J10))),0))"),"1-2") -> 1-2 | L10: =IF(COUNTA(G4,G7,G10,G13,H4,H7,H10,H13,I4,I7,I10,I13,J4,J7,J10,J13)=16,R10,"") -> 3位 | N10: =IFERROR(VALUE(LEFT(K10,FIND("-",K10)-1)),-1) -> 1 | O10: =SUMPRODUCT(IFERROR(--(LEFT(G10:J10,FIND("-",G10:J10)-1)),0)) & "/" & (SUMPRODUCT(IFERROR(--(LEFT(G10:J10,FIND("-",G10:J10)-1)),0)) + SUMPRODUCT(IFERROR(--(RIGHT(G10:J10,LEN(G10:J10)-FIND("-",G10:J10))),0))) -> 6/20 | P10: =IF((COUNTIF($N4,N10)+COUNTIF($N7,N10)+COUNTIF($N10,N10)+COUNTIF($N13,N10))=2, IFERROR(IFS(N10=$N4,IF(VALUE(LEFT(G10,FIND("-",G10)-1))>VALUE(RIGHT(G10,LEN(G10)-FIND("-",G10))),1,0), N10=$N7,IF(VALUE(LEFT(H10,FIND("-",H10)-1))>VALUE(RIGHT(H10,LEN(H10)-FIND("-",H10))),1,0), N10=$N13,IF(VALUE(LEFT(J10,FIND("-",J10)-1))>VALUE(RIGHT(J10,LEN(J10)-FIND("-",J10))),1,0)), ""), "") -> 1 | Q10: {=N10+IF(SUMPRODUCT(--({$N4;$N7;$N10;$N13}=N10))=2,P10*0.1,IF(SUMPRODUCT(--({$N4;$N7;$N10;$N13}=N10))>=3,O11*0.01,0))} -> 1.1 | R10: {=_xlfn.RANK.EQ(Q10, {$Q4;$Q7;$Q10;$Q13}) & "位"} -> 3位
O11: =IFERROR( SUMPRODUCT(IFERROR(--(LEFT(G10:J10,FIND("-",G10:J10)-1)),0)) / (SUMPRODUCT(IFERROR(--(LEFT(G10:J10,FIND("-",G10:J10)-1)),0)) + SUMPRODUCT(IFERROR(--(RIGHT(G10:J10,LEN(G10:J10)-FIND("-",G10:J10))),0))) , 0) -> 0.3
C12: =IFERROR(VLOOKUP(B10&"-"&2,'リスト'!$B:$D,2,FALSE),"") -> 小林 さえ子 | F12: =IFERROR(VLOOKUP(B10&"-"&2,'リスト'!$B:$D,3,FALSE),"") -> カプリス
B13: 4 | C13: =IFERROR(VLOOKUP(B13&"-"&1,'リスト'!$B:$D,2,FALSE),"") -> 三宅 諒弥 | F13: =IFERROR(VLOOKUP(B13&"-"&1,'リスト'!$B:$D,3,FALSE),"") -> 鳥取銀行 | G13: =IFERROR(MID(J4, FIND("-", J4) + 1, 100) & "-" & LEFT(J4, FIND("-", J4) - 1), "") -> 6-4 | H13: =IFERROR(MID(J7, FIND("-", J7) + 1, 100) & "-" & LEFT(J7, FIND("-", J7) - 1), "") -> 5-6 | I13: =IFERROR(MID(J10, FIND("-", J10) + 1, 100) & "-" & LEFT(J10, FIND("-", J10) - 1), "") -> 2-6 | J13: =IFERROR(__xludf.DUMMYFUNCTION("SPARKLINE({1,0})"),"") | K13: =IFERROR(__xludf.DUMMYFUNCTION("SUMPRODUCT(--(REGEXMATCH(TO_TEXT(G13:J13), ""-"")), IFERROR(--(LEFT(G13:J13,FIND(""-"",G13:J13)-1)>RIGHT(G13:J13,LEN(G13:J13)-FIND(""-"",G13:J13))),0)) & ""-"" & SUMPRODUCT(--(REGEXMATCH(TO_TEXT(G13:J13), ""-"")), IFERROR(--(LEFT(G13:J13,FIND(""-"",G13:J1"&"3)-1)<RIGHT(G13:J13,LEN(G13:J13)-FIND(""-"",G13:J13))),0))"),"1-2") -> 1-2 | L13: =IF(COUNTA(G4,G7,G10,G13,H4,H7,H10,H13,I4,I7,I10,I13,J4,J7,J10,J13)=16,R13,"") -> 4位 | N13: =IFERROR(VALUE(LEFT(K13,FIND("-",K13)-1)),-1) -> 1 | O13: =SUMPRODUCT(IFERROR(--(LEFT(G13:J13,FIND("-",G13:J13)-1)),0)) & "/" & (SUMPRODUCT(IFERROR(--(LEFT(G13:J13,FIND("-",G13:J13)-1)),0)) + SUMPRODUCT(IFERROR(--(RIGHT(G13:J13,LEN(G13:J13)-FIND("-",G13:J13))),0))) -> 13/29 | P13: =IF((COUNTIF($N4,N13)+COUNTIF($N7,N13)+COUNTIF($N10,N13)+COUNTIF($N13,N13))=2, IFERROR(IFS(N13=$N4,IF(VALUE(LEFT(G13,FIND("-",G13)-1))>VALUE(RIGHT(G13,LEN(G13)-FIND("-",G13))),1,0), N13=$N7,IF(VALUE(LEFT(H13,FIND("-",H13)-1))>VALUE(RIGHT(H13,LEN(H13)-FIND("-",H13))),1,0), N13=$N10,IF(VALUE(LEFT(I13,FIND("-",I13)-1))>VALUE(RIGHT(I13,LEN(I13)-FIND("-",I13))),1,0)), ""), "") -> 0 | Q13: {=N13+IF(SUMPRODUCT(--({$N4;$N7;$N10;$N13}=N13))=2,P13*0.1,IF(SUMPRODUCT(--({$N4;$N7;$N10;$N13}=N13))>=3,O14*0.01,0))} -> 1 | R13: {=_xlfn.RANK.EQ(Q13, {$Q4;$Q7;$Q10;$Q13}) & "位"} -> 4位
O14: =IFERROR( SUMPRODUCT(IFERROR(--(LEFT(G13:J13,FIND("-",G13:J13)-1)),0)) / (SUMPRODUCT(IFERROR(--(LEFT(G13:J13,FIND("-",G13:J13)-1)),0)) + SUMPRODUCT(IFERROR(--(RIGHT(G13:J13,LEN(G13:J13)-FIND("-",G13:J13))),0))) , 0) -> 0.44827586
C15: =IFERROR(VLOOKUP(B13&"-"&2,'リスト'!$B:$D,2,FALSE),"") -> 山本 桂 | F15: =IFERROR(VLOOKUP(B13&"-"&2,'リスト'!$B:$D,3,FALSE),"") -> たんぽぽ
B17: B | E17: リーグ | I17: =TRIM('予選'!$A$1) -> サンプル
B18: 選手名 | G18: =LEFT(C19, FIND(" ", C19 & " ") - 1) & "・" & LEFT(C21, FIND(" ", C21 & " ") - 1) -> 常村・前田 | H18: =LEFT(C22, FIND(" ", C22 & " ") - 1) & "・" & LEFT(C24, FIND(" ", C24 & " ") - 1) -> 山辺・蓼本 | I18: =LEFT(C25, FIND(" ", C25 & " ") - 1) & "・" & LEFT(C27, FIND(" ", C27 & " ") - 1) -> 高垣・門脇 | J18: =LEFT(C28, FIND(" ", C28 & " ") - 1) & "・" & LEFT(C30, FIND(" ", C30 & " ") - 1) -> 津田・米谷 | K18: 勝敗 | L18: 順位 | N18: 勝数 | O18: 勝率 | P18: 直接対決 | Q18: 判定 | R18: 順位
B19: =B4+4 -> 5 | C19: =IFERROR(VLOOKUP(B19&"-"&1,'リスト'!$B:$D,2,FALSE),"") -> 常村 和仁 | F19: =IFERROR(VLOOKUP(B19&"-"&1,'リスト'!$B:$D,3,FALSE),"") -> 完熟オレンジ | G19: =IFERROR(__xludf.DUMMYFUNCTION("SPARKLINE({1,0})"),"") | H19: 6-0 | I19: 6-0 | J19: 6-0 | K19: =IFERROR(__xludf.DUMMYFUNCTION("SUMPRODUCT(--(REGEXMATCH(TO_TEXT(G19:J19), ""-"")), IFERROR(--(LEFT(G19:J19,FIND(""-"",G19:J19)-1)>RIGHT(G19:J19,LEN(G19:J19)-FIND(""-"",G19:J19))),0)) & ""-"" & SUMPRODUCT(--(REGEXMATCH(TO_TEXT(G19:J19), ""-"")), IFERROR(--(LEFT(G19:J19,FIND(""-"",G19:J1"&"9)-1)<RIGHT(G19:J19,LEN(G19:J19)-FIND(""-"",G19:J19))),0))"),"3-0") -> 3-0 | L19: =IF(COUNTA(G19,G22,G25,G28,H19,H22,H25,H28,I19,I22,I25,I28,J19,J22,J25,J28)=16,R19,"") -> 1位 | N19: =IFERROR(VALUE(LEFT(K19,FIND("-",K19)-1)),-1) -> 3 | O19: =SUMPRODUCT(IFERROR(--(LEFT(G19:J19,FIND("-",G19:J19)-1)),0)) & "/" & (SUMPRODUCT(IFERROR(--(LEFT(G19:J19,FIND("-",G19:J19)-1)),0)) + SUMPRODUCT(IFERROR(--(RIGHT(G19:J19,LEN(G19:J19)-FIND("-",G19:J19))),0))) -> 18/18 | P19: =IF((COUNTIF($N19,N19)+COUNTIF($N22,N19)+COUNTIF($N25,N19)+COUNTIF($N28,N19))=2, IFERROR(IFS(N19=$N22,IF(VALUE(LEFT(H19,FIND("-",H19)-1))>VALUE(RIGHT(H19,LEN(H19)-FIND("-",H19))),1,0), N19=$N25,IF(VALUE(LEFT(I19,FIND("-",I19)-1))>VALUE(RIGHT(I19,LEN(I19)-FIND("-",I19))),1,0), N19=$N28,IF(VALUE(LEFT(J19,FIND("-",J19)-1))>VALUE(RIGHT(J19,LEN(J19)-FIND("-",J19))),1,0)), ""), "") | Q19: {=N19+IF(SUMPRODUCT(--({$N19;$N22;$N25;$N28}=N19))=2,P19*0.1,IF(SUMPRODUCT(--({$N19;$N22;$N25;$N28}=N19))>=3,O20*0.01,0))} -> 3 | R19: {=_xlfn.RANK.EQ(Q19, {$Q19;$Q22;$Q25;$Q28}) & "位"} -> 1位
O20: =IFERROR( SUMPRODUCT(IFERROR(--(LEFT(G19:J19,FIND("-",G19:J19)-1)),0)) / (SUMPRODUCT(IFERROR(--(LEFT(G19:J19,FIND("-",G19:J19)-1)),0)) + SUMPRODUCT(IFERROR(--(RIGHT(G19:J19,LEN(G19:J19)-FIND("-",G19:J19))),0))) , 0) -> 1
C21: =IFERROR(VLOOKUP(B19&"-"&2,'リスト'!$B:$D,2,FALSE),"") -> 前田 良枝 | F21: =IFERROR(VLOOKUP(B19&"-"&2,'リスト'!$B:$D,3,FALSE),"") -> Ｚｏｎｅ
B22: =B7+4 -> 6 | C22: =IFERROR(VLOOKUP(B22&"-"&1,'リスト'!$B:$D,2,FALSE),"") -> 山辺 裕司 | F22: =IFERROR(VLOOKUP(B22&"-"&1,'リスト'!$B:$D,3,FALSE),"") -> ｄｏＭｅ | G22: =IFERROR(MID(H19, FIND("-", H19) + 1, 100) & "-" & LEFT(H19, FIND("-", H19) - 1), "") -> 0-6 | H22: =IFERROR(__xludf.DUMMYFUNCTION("SPARKLINE({1,0})"),"") | I22: 6-0 | J22: 6-0 | K22: =IFERROR(__xludf.DUMMYFUNCTION("SUMPRODUCT(--(REGEXMATCH(TO_TEXT(G22:J22), ""-"")), IFERROR(--(LEFT(G22:J22,FIND(""-"",G22:J22)-1)>RIGHT(G22:J22,LEN(G22:J22)-FIND(""-"",G22:J22))),0)) & ""-"" & SUMPRODUCT(--(REGEXMATCH(TO_TEXT(G22:J22), ""-"")), IFERROR(--(LEFT(G22:J22,FIND(""-"",G22:J2"&"2)-1)<RIGHT(G22:J22,LEN(G22:J22)-FIND(""-"",G22:J22))),0))"),"2-1") -> 2-1 | L22: =IF(COUNTA(G19,G22,G25,G28,H19,H22,H25,H28,I19,I22,I25,I28,J19,J22,J25,J28)=16,R22,"") -> 2位 | N22: =IFERROR(VALUE(LEFT(K22,FIND("-",K22)-1)),-1) -> 2 | O22: =SUMPRODUCT(IFERROR(--(LEFT(G22:J22,FIND("-",G22:J22)-1)),0)) & "/" & (SUMPRODUCT(IFERROR(--(LEFT(G22:J22,FIND("-",G22:J22)-1)),0)) + SUMPRODUCT(IFERROR(--(RIGHT(G22:J22,LEN(G22:J22)-FIND("-",G22:J22))),0))) -> 12/18 | P22: =IF((COUNTIF($N19,N22)+COUNTIF($N22,N22)+COUNTIF($N25,N22)+COUNTIF($N28,N22))=2, IFERROR(IFS(N22=$N19,IF(VALUE(LEFT(G22,FIND("-",G22)-1))>VALUE(RIGHT(G22,LEN(G22)-FIND("-",G22))),1,0), N22=$N25,IF(VALUE(LEFT(I22,FIND("-",I22)-1))>VALUE(RIGHT(I22,LEN(I22)-FIND("-",I22))),1,0), N22=$N28,IF(VALUE(LEFT(J22,FIND("-",J22)-1))>VALUE(RIGHT(J22,LEN(J22)-FIND("-",J22))),1,0)), ""), "") | Q22: {=N22+IF(SUMPRODUCT(--({$N19;$N22;$N25;$N28}=N22))=2,P22*0.1,IF(SUMPRODUCT(--({$N19;$N22;$N25;$N28}=N22))>=3,O23*0.01,0))} -> 2 | R22: {=_xlfn.RANK.EQ(Q22, {$Q19;$Q22;$Q25;$Q28}) & "位"} -> 2位
O23: =IFERROR( SUMPRODUCT(IFERROR(--(LEFT(G22:J22,FIND("-",G22:J22)-1)),0)) / (SUMPRODUCT(IFERROR(--(LEFT(G22:J22,FIND("-",G22:J22)-1)),0)) + SUMPRODUCT(IFERROR(--(RIGHT(G22:J22,LEN(G22:J22)-FIND("-",G22:J22))),0))) , 0) -> 0.66666667
C24: =IFERROR(VLOOKUP(B22&"-"&2,'リスト'!$B:$D,2,FALSE),"") -> 蓼本 裕美 | F24: =IFERROR(VLOOKUP(B22&"-"&2,'リスト'!$B:$D,3,FALSE),"") -> ｄｏＭｅ
B25: =B10+4 -> 7 | C25: =IFERROR(VLOOKUP(B25&"-"&1,'リスト'!$B:$D,2,FALSE),"") -> 高垣 護 | F25: =IFERROR(VLOOKUP(B25&"-"&1,'リスト'!$B:$D,3,FALSE),"") -> Drop☆Shot | G25: =IFERROR(MID(I19, FIND("-", I19) + 1, 100) & "-" & LEFT(I19, FIND("-", I19) - 1), "") -> 0-6 | H25: =IFERROR(MID(I22, FIND("-", I22) + 1, 100) & "-" & LEFT(I22, FIND("-", I22) - 1), "") -> 0-6 | I25: =IFERROR(__xludf.DUMMYFUNCTION("SPARKLINE({1,0})"),"") | J25: 6-0 | K25: =IFERROR(__xludf.DUMMYFUNCTION("SUMPRODUCT(--(REGEXMATCH(TO_TEXT(G25:J25), ""-"")), IFERROR(--(LEFT(G25:J25,FIND(""-"",G25:J25)-1)>RIGHT(G25:J25,LEN(G25:J25)-FIND(""-"",G25:J25))),0)) & ""-"" & SUMPRODUCT(--(REGEXMATCH(TO_TEXT(G25:J25), ""-"")), IFERROR(--(LEFT(G25:J25,FIND(""-"",G25:J2"&"5)-1)<RIGHT(G25:J25,LEN(G25:J25)-FIND(""-"",G25:J25))),0))"),"1-2") -> 1-2 | L25: =IF(COUNTA(G19,G22,G25,G28,H19,H22,H25,H28,I19,I22,I25,I28,J19,J22,J25,J28)=16,R25,"") -> 3位 | N25: =IFERROR(VALUE(LEFT(K25,FIND("-",K25)-1)),-1) -> 1 | O25: =SUMPRODUCT(IFERROR(--(LEFT(G25:J25,FIND("-",G25:J25)-1)),0)) & "/" & (SUMPRODUCT(IFERROR(--(LEFT(G25:J25,FIND("-",G25:J25)-1)),0)) + SUMPRODUCT(IFERROR(--(RIGHT(G25:J25,LEN(G25:J25)-FIND("-",G25:J25))),0))) -> 6/18 | P25: =IF((COUNTIF($N19,N25)+COUNTIF($N22,N25)+COUNTIF($N25,N25)+COUNTIF($N28,N25))=2, IFERROR(IFS(N25=$N19,IF(VALUE(LEFT(G25,FIND("-",G25)-1))>VALUE(RIGHT(G25,LEN(G25)-FIND("-",G25))),1,0), N25=$N22,IF(VALUE(LEFT(H25,FIND("-",H25)-1))>VALUE(RIGHT(H25,LEN(H25)-FIND("-",H25))),1,0), N25=$N28,IF(VALUE(LEFT(J25,FIND("-",J25)-1))>VALUE(RIGHT(J25,LEN(J25)-FIND("-",J25))),1,0)), ""), "") | Q25: {=N25+IF(SUMPRODUCT(--({$N19;$N22;$N25;$N28}=N25))=2,P25*0.1,IF(SUMPRODUCT(--({$N19;$N22;$N25;$N28}=N25))>=3,O26*0.01,0))} -> 1 | R25: {=_xlfn.RANK.EQ(Q25, {$Q19;$Q22;$Q25;$Q28}) & "位"} -> 3位
O26: =IFERROR( SUMPRODUCT(IFERROR(--(LEFT(G25:J25,FIND("-",G25:J25)-1)),0)) / (SUMPRODUCT(IFERROR(--(LEFT(G25:J25,FIND("-",G25:J25)-1)),0)) + SUMPRODUCT(IFERROR(--(RIGHT(G25:J25,LEN(G25:J25)-FIND("-",G25:J25))),0))) , 0) -> 0.33333333
C27: =IFERROR(VLOOKUP(B25&"-"&2,'リスト'!$B:$D,2,FALSE),"") -> 門脇 春美 | F27: =IFERROR(VLOOKUP(B25&"-"&2,'リスト'!$B:$D,3,FALSE),"") -> あみたま
B28: =B13+4 -> 8 | C28: =IFERROR(VLOOKUP(B28&"-"&1,'リスト'!$B:$D,2,FALSE),"") -> 津田 智広 | F28: =IFERROR(VLOOKUP(B28&"-"&1,'リスト'!$B:$D,3,FALSE),"") -> ノーレット７ | G28: =IFERROR(MID(J19, FIND("-", J19) + 1, 100) & "-" & LEFT(J19, FIND("-", J19) - 1), "") -> 0-6 | H28: =IFERROR(MID(J22, FIND("-", J22) + 1, 100) & "-" & LEFT(J22, FIND("-", J22) - 1), "") -> 0-6 | I28: =IFERROR(MID(J25, FIND("-", J25) + 1, 100) & "-" & LEFT(J25, FIND("-", J25) - 1), "") -> 0-6 | J28: =IFERROR(__xludf.DUMMYFUNCTION("SPARKLINE({1,0})"),"") | K28: =IFERROR(__xludf.DUMMYFUNCTION("SUMPRODUCT(--(REGEXMATCH(TO_TEXT(G28:J28), ""-"")), IFERROR(--(LEFT(G28:J28,FIND(""-"",G28:J28)-1)>RIGHT(G28:J28,LEN(G28:J28)-FIND(""-"",G28:J28))),0)) & ""-"" & SUMPRODUCT(--(REGEXMATCH(TO_TEXT(G28:J28), ""-"")), IFERROR(--(LEFT(G28:J28,FIND(""-"",G28:J2"&"8)-1)<RIGHT(G28:J28,LEN(G28:J28)-FIND(""-"",G28:J28))),0))"),"0-3") -> 0-3 | L28: =IF(COUNTA(G19,G22,G25,G28,H19,H22,H25,H28,I19,I22,I25,I28,J19,J22,J25,J28)=16,R28,"") -> 4位 | N28: =IFERROR(VALUE(LEFT(K28,FIND("-",K28)-1)),-1) -> 0 | O28: =SUMPRODUCT(IFERROR(--(LEFT(G28:J28,FIND("-",G28:J28)-1)),0)) & "/" & (SUMPRODUCT(IFERROR(--(LEFT(G28:J28,FIND("-",G28:J28)-1)),0)) + SUMPRODUCT(IFERROR(--(RIGHT(G28:J28,LEN(G28:J28)-FIND("-",G28:J28))),0))) -> 0/18 | P28: =IF((COUNTIF($N19,N28)+COUNTIF($N22,N28)+COUNTIF($N25,N28)+COUNTIF($N28,N28))=2, IFERROR(IFS(N28=$N19,IF(VALUE(LEFT(G28,FIND("-",G28)-1))>VALUE(RIGHT(G28,LEN(G28)-FIND("-",G28))),1,0), N28=$N22,IF(VALUE(LEFT(H28,FIND("-",H28)-1))>VALUE(RIGHT(H28,LEN(H28)-FIND("-",H28))),1,0), N28=$N25,IF(VALUE(LEFT(I28,FIND("-",I28)-1))>VALUE(RIGHT(I28,LEN(I28)-FIND("-",I28))),1,0)), ""), "") | Q28: {=N28+IF(SUMPRODUCT(--({$N19;$N22;$N25;$N28}=N28))=2,P28*0.1,IF(SUMPRODUCT(--({$N19;$N22;$N25;$N28}=N28))>=3,O29*0.01,0))} -> 0 | R28: {=_xlfn.RANK.EQ(Q28, {$Q19;$Q22;$Q25;$Q28}) & "位"} -> 4位
O29: =IFERROR( SUMPRODUCT(IFERROR(--(LEFT(G28:J28,FIND("-",G28:J28)-1)),0)) / (SUMPRODUCT(IFERROR(--(LEFT(G28:J28,FIND("-",G28:J28)-1)),0)) + SUMPRODUCT(IFERROR(--(RIGHT(G28:J28,LEN(G28:J28)-FIND("-",G28:J28))),0))) , 0) -> 0
C30: =IFERROR(VLOOKUP(B28&"-"&2,'リスト'!$B:$D,2,FALSE),"") -> 米谷 さおり | F30: =IFERROR(VLOOKUP(B28&"-"&2,'リスト'!$B:$D,3,FALSE),"") -> フリー
B32: C | E32: リーグ | I32: =TRIM('予選'!$A$1) -> サンプル
B33: 選手名 | G33: =LEFT(C34, FIND(" ", C34 & " ") - 1) & "・" & LEFT(C36, FIND(" ", C36 & " ") - 1) -> 近藤・前田 | H33: =LEFT(C37, FIND(" ", C37 & " ") - 1) & "・" & LEFT(C39, FIND(" ", C39 & " ") - 1) -> 林原・林原 | I33: =LEFT(C40, FIND(" ", C40 & " ") - 1) & "・" & LEFT(C42, FIND(" ", C42 & " ") - 1) -> 和気・長川 | J33: =LEFT(C43, FIND(" ", C43 & " ") - 1) & "・" & LEFT(C45, FIND(" ", C45 & " ") - 1) -> 山下・田苗 | K33: 勝敗 | L33: 順位 | N33: 勝数 | O33: 勝率 | P33: 直接対決 | Q33: スコア | R33: 順位
B34: =B19+4 -> 9 | C34: =IFERROR(VLOOKUP(B34&"-"&1,'リスト'!$B:$D,2,FALSE),"") -> 近藤 哲生 | F34: =IFERROR(VLOOKUP(B34&"-"&1,'リスト'!$B:$D,3,FALSE),"") -> 因幡打輪 | G34: =IFERROR(__xludf.DUMMYFUNCTION("SPARKLINE({1,0})"),"") | H34: 0-0 | I34: 6-0 | J34: 6-0 | K34: =IFERROR(__xludf.DUMMYFUNCTION("SUMPRODUCT(--(REGEXMATCH(TO_TEXT(G34:J34), ""-"")), IFERROR(--(LEFT(G34:J34,FIND(""-"",G34:J34)-1)>RIGHT(G34:J34,LEN(G34:J34)-FIND(""-"",G34:J34))),0)) & ""-"" & SUMPRODUCT(--(REGEXMATCH(TO_TEXT(G34:J34), ""-"")), IFERROR(--(LEFT(G34:J34,FIND(""-"",G34:J3"&"4)-1)<RIGHT(G34:J34,LEN(G34:J34)-FIND(""-"",G34:J34))),0))"),"2-0") -> 2-0 | L34: =IF(COUNTA(G34,G37,G40,G43,H34,H37,H40,H43,I34,I37,I40,I43,J34,J37,J40,J43)=16,R34,"") -> 1位 | N34: =IFERROR(VALUE(LEFT(K34,FIND("-",K34)-1)),-1) -> 2 | O34: =SUMPRODUCT(IFERROR(--(LEFT(G34:J34,FIND("-",G34:J34)-1)),0)) & "/" & (SUMPRODUCT(IFERROR(--(LEFT(G34:J34,FIND("-",G34:J34)-1)),0)) + SUMPRODUCT(IFERROR(--(RIGHT(G34:J34,LEN(G34:J34)-FIND("-",G34:J34))),0))) -> 12/12 | P34: =IF((COUNTIF($N34,N34)+COUNTIF($N37,N34)+COUNTIF($N40,N34)+COUNTIF($N43,N34))=2, IFERROR(IFS(N34=$N37,IF(VALUE(LEFT(H34,FIND("-",H34)-1))>VALUE(RIGHT(H34,LEN(H34)-FIND("-",H34))),1,0), N34=$N40,IF(VALUE(LEFT(I34,FIND("-",I34)-1))>VALUE(RIGHT(I34,LEN(I34)-FIND("-",I34))),1,0), N34=$N43,IF(VALUE(LEFT(J34,FIND("-",J34)-1))>VALUE(RIGHT(J34,LEN(J34)-FIND("-",J34))),1,0)), ""), "") | Q34: {=N34+IF(SUMPRODUCT(--({$N34;$N37;$N40;$N43}=N34))=2,P34*0.1,IF(SUMPRODUCT(--({$N34;$N37;$N40;$N43}=N34))>=3,O35*0.01,0))} -> 2 | R34: {=_xlfn.RANK.EQ(Q34, {$Q34;$Q37;$Q40;$Q43}) & "位"} -> 1位
O35: =IFERROR( SUMPRODUCT(IFERROR(--(LEFT(G34:J34,FIND("-",G34:J34)-1)),0)) / (SUMPRODUCT(IFERROR(--(LEFT(G34:J34,FIND("-",G34:J34)-1)),0)) + SUMPRODUCT(IFERROR(--(RIGHT(G34:J34,LEN(G34:J34)-FIND("-",G34:J34))),0))) , 0) -> 1
C36: =IFERROR(VLOOKUP(B34&"-"&2,'リスト'!$B:$D,2,FALSE),"") -> 前田 陽子 | F36: =IFERROR(VLOOKUP(B34&"-"&2,'リスト'!$B:$D,3,FALSE),"") -> フリー
B37: =B22+4 -> 10 | C37: =IFERROR(VLOOKUP(B37&"-"&1,'リスト'!$B:$D,2,FALSE),"") -> 林原 政幸 | F37: =IFERROR(VLOOKUP(B37&"-"&1,'リスト'!$B:$D,3,FALSE),"") -> フリー | G37: =IFERROR(MID(H34, FIND("-", H34) + 1, 100) & "-" & LEFT(H34, FIND("-", H34) - 1), "") -> 0-0 | H37: =IFERROR(__xludf.DUMMYFUNCTION("SPARKLINE({1,0})"),"") | I37: 0-0 | J37: 0-0 | K37: =IFERROR(__xludf.DUMMYFUNCTION("SUMPRODUCT(--(REGEXMATCH(TO_TEXT(G37:J37), ""-"")), IFERROR(--(LEFT(G37:J37,FIND(""-"",G37:J37)-1)>RIGHT(G37:J37,LEN(G37:J37)-FIND(""-"",G37:J37))),0)) & ""-"" & SUMPRODUCT(--(REGEXMATCH(TO_TEXT(G37:J37), ""-"")), IFERROR(--(LEFT(G37:J37,FIND(""-"",G37:J3"&"7)-1)<RIGHT(G37:J37,LEN(G37:J37)-FIND(""-"",G37:J37))),0))"),"0-0") -> 0-0 | L37: W.O | N37: =IFERROR(VALUE(LEFT(K37,FIND("-",K37)-1)),-1) -> 0 | O37: =SUMPRODUCT(IFERROR(--(LEFT(G37:J37,FIND("-",G37:J37)-1)),0)) & "/" & (SUMPRODUCT(IFERROR(--(LEFT(G37:J37,FIND("-",G37:J37)-1)),0)) + SUMPRODUCT(IFERROR(--(RIGHT(G37:J37,LEN(G37:J37)-FIND("-",G37:J37))),0))) -> 0/0 | P37: =IF((COUNTIF($N34,N37)+COUNTIF($N37,N37)+COUNTIF($N40,N37)+COUNTIF($N43,N37))=2, IFERROR(IFS(N37=$N34,IF(VALUE(LEFT(G37,FIND("-",G37)-1))>VALUE(RIGHT(G37,LEN(G37)-FIND("-",G37))),1,0), N37=$N40,IF(VALUE(LEFT(I37,FIND("-",I37)-1))>VALUE(RIGHT(I37,LEN(I37)-FIND("-",I37))),1,0), N37=$N43,IF(VALUE(LEFT(J37,FIND("-",J37)-1))>VALUE(RIGHT(J37,LEN(J37)-FIND("-",J37))),1,0)), ""), "") -> 0 | Q37: {=N37+IF(SUMPRODUCT(--({$N34;$N37;$N40;$N43}=N37))=2,P37*0.1,IF(SUMPRODUCT(--({$N34;$N37;$N40;$N43}=N37))>=3,O38*0.01,0))} -> 0 | R37: {=_xlfn.RANK.EQ(Q37, {$Q34;$Q37;$Q40;$Q43}) & "位"} -> 3位
O38: =IFERROR( SUMPRODUCT(IFERROR(--(LEFT(G37:J37,FIND("-",G37:J37)-1)),0)) / (SUMPRODUCT(IFERROR(--(LEFT(G37:J37,FIND("-",G37:J37)-1)),0)) + SUMPRODUCT(IFERROR(--(RIGHT(G37:J37,LEN(G37:J37)-FIND("-",G37:J37))),0))) , 0) -> 0
C39: =IFERROR(VLOOKUP(B37&"-"&2,'リスト'!$B:$D,2,FALSE),"") -> 林原 史子 | F39: =IFERROR(VLOOKUP(B37&"-"&2,'リスト'!$B:$D,3,FALSE),"") -> フリー
B40: =B25+4 -> 11 | C40: =IFERROR(VLOOKUP(B40&"-"&1,'リスト'!$B:$D,2,FALSE),"") -> 和気 久 | F40: =IFERROR(VLOOKUP(B40&"-"&1,'リスト'!$B:$D,3,FALSE),"") -> ＢＳＣ | G40: =IFERROR(MID(I34, FIND("-", I34) + 1, 100) & "-" & LEFT(I34, FIND("-", I34) - 1), "") -> 0-6 | H40: =IFERROR(MID(I37, FIND("-", I37) + 1, 100) & "-" & LEFT(I37, FIND("-", I37) - 1), "") -> 0-0 | I40: =IFERROR(__xludf.DUMMYFUNCTION("SPARKLINE({1,0})"),"") | J40: 6-0 | K40: =IFERROR(__xludf.DUMMYFUNCTION("SUMPRODUCT(--(REGEXMATCH(TO_TEXT(G40:J40), ""-"")), IFERROR(--(LEFT(G40:J40,FIND(""-"",G40:J40)-1)>RIGHT(G40:J40,LEN(G40:J40)-FIND(""-"",G40:J40))),0)) & ""-"" & SUMPRODUCT(--(REGEXMATCH(TO_TEXT(G40:J40), ""-"")), IFERROR(--(LEFT(G40:J40,FIND(""-"",G40:J4"&"0)-1)<RIGHT(G40:J40,LEN(G40:J40)-FIND(""-"",G40:J40))),0))"),"1-1") -> 1-1 | L40: =IF(COUNTA(G34,G37,G40,G43,H34,H37,H40,H43,I34,I37,I40,I43,J34,J37,J40,J43)=16,R40,"") -> 2位 | N40: =IFERROR(VALUE(LEFT(K40,FIND("-",K40)-1)),-1) -> 1 | O40: =SUMPRODUCT(IFERROR(--(LEFT(G40:J40,FIND("-",G40:J40)-1)),0)) & "/" & (SUMPRODUCT(IFERROR(--(LEFT(G40:J40,FIND("-",G40:J40)-1)),0)) + SUMPRODUCT(IFERROR(--(RIGHT(G40:J40,LEN(G40:J40)-FIND("-",G40:J40))),0))) -> 6/12 | P40: =IF((COUNTIF($N34,N40)+COUNTIF($N37,N40)+COUNTIF($N40,N40)+COUNTIF($N43,N40))=2, IFERROR(IFS(N40=$N34,IF(VALUE(LEFT(G40,FIND("-",G40)-1))>VALUE(RIGHT(G40,LEN(G40)-FIND("-",G40))),1,0), N40=$N37,IF(VALUE(LEFT(H40,FIND("-",H40)-1))>VALUE(RIGHT(H40,LEN(H40)-FIND("-",H40))),1,0), N40=$N43,IF(VALUE(LEFT(J40,FIND("-",J40)-1))>VALUE(RIGHT(J40,LEN(J40)-FIND("-",J40))),1,0)), ""), "") | Q40: {=N40+IF(SUMPRODUCT(--({$N34;$N37;$N40;$N43}=N40))=2,P40*0.1,IF(SUMPRODUCT(--({$N34;$N37;$N40;$N43}=N40))>=3,O41*0.01,0))} -> 1 | R40: {=_xlfn.RANK.EQ(Q40, {$Q34;$Q37;$Q40;$Q43}) & "位"} -> 2位
O41: =IFERROR( SUMPRODUCT(IFERROR(--(LEFT(G40:J40,FIND("-",G40:J40)-1)),0)) / (SUMPRODUCT(IFERROR(--(LEFT(G40:J40,FIND("-",G40:J40)-1)),0)) + SUMPRODUCT(IFERROR(--(RIGHT(G40:J40,LEN(G40:J40)-FIND("-",G40:J40))),0))) , 0) -> 0.5
C42: =IFERROR(VLOOKUP(B40&"-"&2,'リスト'!$B:$D,2,FALSE),"") -> 長川 朱美 | F42: =IFERROR(VLOOKUP(B40&"-"&2,'リスト'!$B:$D,3,FALSE),"") -> ロランギャロス
B43: =B28+4 -> 12 | C43: =IFERROR(VLOOKUP(B43&"-"&1,'リスト'!$B:$D,2,FALSE),"") -> 山下 悠樹 | F43: =IFERROR(VLOOKUP(B43&"-"&1,'リスト'!$B:$D,3,FALSE),"") -> ｏｆｆ | G43: =IFERROR(MID(J34, FIND("-", J34) + 1, 100) & "-" & LEFT(J34, FIND("-", J34) - 1), "") -> 0-6 | H43: =IFERROR(MID(J37, FIND("-", J37) + 1, 100) & "-" & LEFT(J37, FIND("-", J37) - 1), "") -> 0-0 | I43: =IFERROR(MID(J40, FIND("-", J40) + 1, 100) & "-" & LEFT(J40, FIND("-", J40) - 1), "") -> 0-6 | J43: =IFERROR(__xludf.DUMMYFUNCTION("SPARKLINE({1,0})"),"") | K43: =IFERROR(__xludf.DUMMYFUNCTION("SUMPRODUCT(--(REGEXMATCH(TO_TEXT(G43:J43), ""-"")), IFERROR(--(LEFT(G43:J43,FIND(""-"",G43:J43)-1)>RIGHT(G43:J43,LEN(G43:J43)-FIND(""-"",G43:J43))),0)) & ""-"" & SUMPRODUCT(--(REGEXMATCH(TO_TEXT(G43:J43), ""-"")), IFERROR(--(LEFT(G43:J43,FIND(""-"",G43:J4"&"3)-1)<RIGHT(G43:J43,LEN(G43:J43)-FIND(""-"",G43:J43))),0))"),"0-2") -> 0-2 | L43: =IF(COUNTA(G34,G37,G40,G43,H34,H37,H40,H43,I34,I37,I40,I43,J34,J37,J40,J43)=16,R43,"") -> 3位 | N43: =IFERROR(VALUE(LEFT(K43,FIND("-",K43)-1)),-1) -> 0 | O43: =SUMPRODUCT(IFERROR(--(LEFT(G43:J43,FIND("-",G43:J43)-1)),0)) & "/" & (SUMPRODUCT(IFERROR(--(LEFT(G43:J43,FIND("-",G43:J43)-1)),0)) + SUMPRODUCT(IFERROR(--(RIGHT(G43:J43,LEN(G43:J43)-FIND("-",G43:J43))),0))) -> 0/12 | P43: =IF((COUNTIF($N34,N43)+COUNTIF($N37,N43)+COUNTIF($N40,N43)+COUNTIF($N43,N43))=2, IFERROR(IFS(N43=$N34,IF(VALUE(LEFT(G43,FIND("-",G43)-1))>VALUE(RIGHT(G43,LEN(G43)-FIND("-",G43))),1,0), N43=$N37,IF(VALUE(LEFT(H43,FIND("-",H43)-1))>VALUE(RIGHT(H43,LEN(H43)-FIND("-",H43))),1,0), N43=$N40,IF(VALUE(LEFT(I43,FIND("-",I43)-1))>VALUE(RIGHT(I43,LEN(I43)-FIND("-",I43))),1,0)), ""), "") -> 0 | Q43: {=N43+IF(SUMPRODUCT(--({$N34;$N37;$N40;$N43}=N43))=2,P43*0.1,IF(SUMPRODUCT(--({$N34;$N37;$N40;$N43}=N43))>=3,O44*0.01,0))} -> 0 | R43: {=_xlfn.RANK.EQ(Q43, {$Q34;$Q37;$Q40;$Q43}) & "位"} -> 3位
...

Sheet 予選L結果(2)
B2: L | E2: リーグ | J2: =TRIM('予選'!$A$1) -> サンプル
B3: 選手名 | G3: =LEFT(C4, FIND(" ", C4 & " ") - 1) & "・" & LEFT(C6, FIND(" ", C6 & " ") - 1) -> 小椋・前田 | H3: =LEFT(C7, FIND(" ", C7 & " ") - 1) & "・" & LEFT(C9, FIND(" ", C9 & " ") - 1) -> 住吉・福浜 | I3: =LEFT(C10, FIND(" ", C10 & " ") - 1) & "・" & LEFT(C12, FIND(" ", C12 & " ") - 1) -> 吉田・岡田 | J3: =LEFT(C13, FIND(" ", C13 & " ") - 1) & "・" & LEFT(C15, FIND(" ", C15 & " ") - 1) -> 藤田・藤田 | K3: =LEFT(C16, FIND(" ", C16 & " ") - 1) & "・" & LEFT(C18, FIND(" ", C18 & " ") - 1) -> 清水・大田 | L3: 勝敗 | M3: 順位 | O3: 勝数 | P3: 勝率 | Q3: 直接対決 | R3: 判定 | S3: 順位
B4: 45 | C4: =IFERROR(VLOOKUP(B4&"-"&1,'リスト'!$B:$D,2,FALSE),"") -> 小椋 浩二 | F4: =IFERROR(VLOOKUP(B4&"-"&1,'リスト'!$B:$D,3,FALSE),"") -> てーくおふ | G4: =IFERROR(__xludf.DUMMYFUNCTION("SPARKLINE({1,0})"),"") | H4: 6-0 | I4: 6-0 | J4: 6-0 | K4: 6-0 | L4: =IFERROR(__xludf.DUMMYFUNCTION("SUMPRODUCT(--(REGEXMATCH(TO_TEXT(G4:K4), ""-"")), IFERROR(--(LEFT(G4:K4,FIND(""-"",G4:K4)-1)>RIGHT(G4:K4,LEN(G4:K4)-FIND(""-"",G4:K4))),0)) & ""-"" & SUMPRODUCT(--(REGEXMATCH(TO_TEXT(G4:K4), ""-"")), IFERROR(--(LEFT(G4:K4,FIND(""-"",G4:K4)-1)<RIGHT(G4:K4,"&"LEN(G4:K4)-FIND(""-"",G4:K4))),0))"),"4-0") -> 4-0 | M4: =IF(COUNTA(G4,H4,H7,H10,H13,I4,I7,I10,I13,J4,J7,J10,J13,K4,K7,K10,K13,G7,G10,G13,G16,H16,I16,J16,K16)=25,S4,"") -> 1位 | O4: =IFERROR(VALUE(LEFT(L4,FIND("-",L4)-1)),-1) -> 4 | P4: =SUMPRODUCT(IFERROR(--(LEFT(H4:K4,FIND("-",H4:K4)-1)),0)) & "/" & (SUMPRODUCT(IFERROR(--(LEFT(H4:K4,FIND("-",H4:K4)-1)),0)) + SUMPRODUCT(IFERROR(--(RIGHT(H4:K4,LEN(H4:K4)-FIND("-",H4:K4))),0))) -> 24/24 | Q4: {=IF(SUMPRODUCT(--({$O4;$O7;$O10;$O13;$O16}=O4))=2, IFERROR(IFS(O4=$O7,IF(VALUE(LEFT(H4,FIND("-",H4)-1))>VALUE(RIGHT(H4,LEN(H4)-FIND("-",H4))),1,0),O4=$O10,IF(VALUE(LEFT(I4,FIND("-",I4)-1))>VALUE(RIGHT(I4,LEN(I4)-FIND("-",I4))),1,0),O4=$O13,IF(VALUE(LEFT(J4,FIND("-",J4)-1))>VALUE(RIGHT(J4,LEN(J4)-FIND("-",J4))),1,0),O4=$O16,IF(VALUE(LEFT(K4,FIND("-",K4)-1))>VALUE(RIGHT(K4,LEN(K4)-FIND("-",K4))),1,0)),""),"")} | R4: {=O4+IF(SUMPRODUCT(--({O4;O7;O10;O13;O16}=O4))=2,Q4*0.1,IF(SUMPRODUCT(--({O4;O7;O10;O13;O16}=O4))>=3,P5*0.01,0))} -> 4 | S4: {=_xlfn.RANK.EQ(R4, {R4;R7;R10;R13;R16}) & "位"} -> 1位
P5: =IFERROR( SUMPRODUCT(IFERROR(--(LEFT(H4:K4,FIND("-",H4:K4)-1)),0)) / (SUMPRODUCT(IFERROR(--(LEFT(H4:K4,FIND("-",H4:K4)-1)),0)) + SUMPRODUCT(IFERROR(--(RIGHT(H4:K4,LEN(H4:K4)-FIND("-",H4:K4))),0))) , 0) -> 1
C6: =IFERROR(VLOOKUP(B4&"-"&2,'リスト'!$B:$D,2,FALSE),"") -> 前田 美由紀 | F6: =IFERROR(VLOOKUP(B4&"-"&2,'リスト'!$B:$D,3,FALSE),"") -> てーくおふ
B7: 46 | C7: =IFERROR(VLOOKUP(B7&"-"&1,'リスト'!$B:$D,2,FALSE),"") -> 住吉 俊輝 | F7: =IFERROR(VLOOKUP(B7&"-"&1,'リスト'!$B:$D,3,FALSE),"") -> プラセール | G7: =IFERROR(MID(H4, FIND("-", H4) + 1, 100) & "-" & LEFT(H4, FIND("-", H4) - 1), "") -> 0-6 | H7: =IFERROR(__xludf.DUMMYFUNCTION("SPARKLINE({1,0})"),"") | I7: 6-0 | J7: 6-0 | K7: 6-0 | L7: =IFERROR(__xludf.DUMMYFUNCTION("SUMPRODUCT(--(REGEXMATCH(TO_TEXT(G7:K7), ""-"")), IFERROR(--(LEFT(G7:K7,FIND(""-"",G7:K7)-1)>RIGHT(G7:K7,LEN(G7:K7)-FIND(""-"",G7:K7))),0)) & ""-"" & SUMPRODUCT(--(REGEXMATCH(TO_TEXT(G7:K7), ""-"")), IFERROR(--(LEFT(G7:K7,FIND(""-"",G7:K7)-1)<RIGHT(G7:K7,"&"LEN(G7:K7)-FIND(""-"",G7:K7))),0))"),"3-1") -> 3-1 | M7: =IF(COUNTA($G$4,$H$4,$H$7,$H$10,$H$13,$I$4,$I$7,$I$10,$I$13,$J$4,$J$7,$J$10,$J$13,$K$4,$K$7,$K$10,$K$13,$G$7,$G$10,$G$13,$G$16,$H$16,$I$16,$J$16,$K$16)=25,S7,"") -> 2位 | O7: =IFERROR(VALUE(LEFT(L7,FIND("-",L7)-1)),-1) -> 3 | P7: =SUMPRODUCT(IFERROR(--(LEFT(G7:K7,FIND("-",G7:K7)-1)),0)) & "/" & (SUMPRODUCT(IFERROR(--(LEFT(G7:K7,FIND("-",G7:K7)-1)),0)) + SUMPRODUCT(IFERROR(--(RIGHT(G7:K7,LEN(G7:K7)-FIND("-",G7:K7))),0))) -> 18/24 | Q7: {=IF(SUMPRODUCT(--({O4;O7;O10;O13;O16}=O7))=2, IFERROR(IFS(O7=$O4,IF(VALUE(LEFT(H4,FIND("-",H4)-1))<VALUE(RIGHT(H4,LEN(H4)-FIND("-",H4))),1,0),O7=$O10,IF(VALUE(LEFT(I7,FIND("-",I7)-1))>VALUE(RIGHT(I7,LEN(I7)-FIND("-",I7))),1,0),O7=$O13,IF(VALUE(LEFT(J7,FIND("-",J7)-1))>VALUE(RIGHT(J7,LEN(J7)-FIND("-",J7))),1,0),O7=$O16,IF(VALUE(LEFT(K7,FIND("-",K7)-1))>VALUE(RIGHT(K7,LEN(K7)-FIND("-",K7))),1,0)),""),"")} | R7: {=O7+IF(SUMPRODUCT(--({O4;O7;O10;O13;O16}=O7))=2,Q7*0.1,IF(SUMPRODUCT(--({O4;O7;O10;O13;O16}=O7))>=3,P8*0.01,0))} -> 3 | S7: {=_xlfn.RANK.EQ(R7, {R4;R7;R10;R13;R16}) & "位"} -> 2位
P8: =IFERROR( SUMPRODUCT(IFERROR(--(LEFT(G7:K7,FIND("-",G7:K7)-1)),0)) / (SUMPRODUCT(IFERROR(--(LEFT(G7:K7,FIND("-",G7:K7)-1)),0)) + SUMPRODUCT(IFERROR(--(RIGHT(G7:K7,LEN(G7:K7)-FIND("-",G7:K7))),0))) , 0) -> 0.75
C9: =IFERROR(VLOOKUP(B7&"-"&2,'リスト'!$B:$D,2,FALSE),"") -> 福浜 美佐緒 | F9: =IFERROR(VLOOKUP(B7&"-"&2,'リスト'!$B:$D,3,FALSE),"") -> プラセール
B10: 47 | C10: =IFERROR(VLOOKUP(B10&"-"&1,'リスト'!$B:$D,2,FALSE),"") -> 吉田 浩士 | F10: =IFERROR(VLOOKUP(B10&"-"&1,'リスト'!$B:$D,3,FALSE),"") -> ノーレット７ | G10: =IFERROR(MID(I4, FIND("-", I4) + 1, 100) & "-" & LEFT(I4, FIND("-", I4) - 1), "") -> 0-6 | H10: =IFERROR(MID(I7, FIND("-", I7) + 1, 100) & "-" & LEFT(I7, FIND("-", I7) - 1), "") -> 0-6 | I10: =IFERROR(__xludf.DUMMYFUNCTION("SPARKLINE({1,0})"),"") | J10: 6-0 | K10: 6-0 | L10: =IFERROR(__xludf.DUMMYFUNCTION("SUMPRODUCT(--(REGEXMATCH(TO_TEXT(G10:K10), ""-"")), IFERROR(--(LEFT(G10:K10,FIND(""-"",G10:K10)-1)>RIGHT(G10:K10,LEN(G10:K10)-FIND(""-"",G10:K10))),0)) & ""-"" & SUMPRODUCT(--(REGEXMATCH(TO_TEXT(G10:K10), ""-"")), IFERROR(--(LEFT(G10:K10,FIND(""-"",G10:K1"&"0)-1)<RIGHT(G10:K10,LEN(G10:K10)-FIND(""-"",G10:K10))),0))"),"2-2") -> 2-2 | M10: =IF(COUNTA($G$4,$H$4,$H$7,$H$10,$H$13,$I$4,$I$7,$I$10,$I$13,$J$4,$J$7,$J$10,$J$13,$K$4,$K$7,$K$10,$K$13,$G$7,$G$10,$G$13,$G$16,$H$16,$I$16,$J$16,$K$16)=25,S10,"") -> 3位 | O10: =IFERROR(VALUE(LEFT(L10,FIND("-",L10)-1)),-1) -> 2 | P10: =SUMPRODUCT(IFERROR(--(LEFT(G10:K10,FIND("-",G10:K10)-1)),0)) & "/" & (SUMPRODUCT(IFERROR(--(LEFT(G10:K10,FIND("-",G10:K10)-1)),0)) + SUMPRODUCT(IFERROR(--(RIGHT(G10:K10,LEN(G10:K10)-FIND("-",G10:K10))),0))) -> 12/24 | Q10: {=IF(SUMPRODUCT(--({O4;O7;O10;O13;O16}=O10))=2, IFERROR(IFS(O10=$O4,IF(VALUE(LEFT(I4,FIND("-",I4)-1))<VALUE(RIGHT(I4,LEN(I4)-FIND("-",I4))),1,0),O10=$O7,IF(VALUE(LEFT(I7,FIND("-",I7)-1))<VALUE(RIGHT(I7,LEN(I7)-FIND("-",I7))),1,0),O10=$O13,IF(VALUE(LEFT(J10,FIND("-",J10)-1))>VALUE(RIGHT(J10,LEN(J10)-FIND("-",J10))),1,0),O10=$O16,IF(VALUE(LEFT(K10,FIND("-",K10)-1))>VALUE(RIGHT(K10,LEN(K10)-FIND("-",K10))),1,0)),""),"")} | R10: {=O10+IF(SUMPRODUCT(--({O4;O7;O10;O13;O16}=O10))=2,Q10*0.1,IF(SUMPRODUCT(--({O4;O7;O10;O13;O16}=O10))>=3,P11*0.01,0))} -> 2 | S10: {=_xlfn.RANK.EQ(R10, {R4;R7;R10;R13;R16}) & "位"} -> 3位
P11: =IFERROR( SUMPRODUCT(IFERROR(--(LEFT(G10:K10,FIND("-",G10:K10)-1)),0)) / (SUMPRODUCT(IFERROR(--(LEFT(G10:K10,FIND("-",G10:K10)-1)),0)) + SUMPRODUCT(IFERROR(--(RIGHT(G10:K10,LEN(G10:K10)-FIND("-",G10:K10))),0))) , 0) -> 0.5
C12: =IFERROR(VLOOKUP(B10&"-"&2,'リスト'!$B:$D,2,FALSE),"") -> 岡田 友子 | F12: =IFERROR(VLOOKUP(B10&"-"&2,'リスト'!$B:$D,3,FALSE),"") -> ノーレット７
B13: 48 | C13: =IFERROR(VLOOKUP(B13&"-"&1,'リスト'!$B:$D,2,FALSE),"") -> 藤田 和幸 | F13: =IFERROR(VLOOKUP(B13&"-"&1,'リスト'!$B:$D,3,FALSE),"") -> フリー | G13: =IFERROR(MID(J4, FIND("-", J4) + 1, 100) & "-" & LEFT(J4, FIND("-", J4) - 1), "") -> 0-6 | H13: =IFERROR(MID(J7, FIND("-", J7) + 1, 100) & "-" & LEFT(J7, FIND("-", J7) - 1), "") -> 0-6 | I13: =IFERROR(MID(J10, FIND("-", J10) + 1, 100) & "-" & LEFT(J10, FIND("-", J10) - 1), "") -> 0-6 | J13: =IFERROR(__xludf.DUMMYFUNCTION("SPARKLINE({1,0})"),"") | K13: 6-0 | L13: =IFERROR(__xludf.DUMMYFUNCTION("SUMPRODUCT(--(REGEXMATCH(TO_TEXT(G13:K13), ""-"")), IFERROR(--(LEFT(G13:K13,FIND(""-"",G13:K13)-1)>RIGHT(G13:K13,LEN(G13:K13)-FIND(""-"",G13:K13))),0)) & ""-"" & SUMPRODUCT(--(REGEXMATCH(TO_TEXT(G13:K13), ""-"")), IFERROR(--(LEFT(G13:K13,FIND(""-"",G13:K1"&"3)-1)<RIGHT(G13:K13,LEN(G13:K13)-FIND(""-"",G13:K13))),0))"),"1-3") -> 1-3 | M13: =IF(COUNTA($G$4,$H$4,$H$7,$H$10,$H$13,$I$4,$I$7,$I$10,$I$13,$J$4,$J$7,$J$10,$J$13,$K$4,$K$7,$K$10,$K$13,$G$7,$G$10,$G$13,$G$16,$H$16,$I$16,$J$16,$K$16)=25,S13,"") -> 4位 | O13: =IFERROR(VALUE(LEFT(L13,FIND("-",L13)-1)),-1) -> 1 | P13: =SUMPRODUCT(IFERROR(--(LEFT(G13:K13,FIND("-",G13:K13)-1)),0)) & "/" & (SUMPRODUCT(IFERROR(--(LEFT(G13:K13,FIND("-",G13:K13)-1)),0)) + SUMPRODUCT(IFERROR(--(RIGHT(G13:K13,LEN(G13:K13)-FIND("-",G13:K13))),0))) -> 6/24 | Q13: {=IF(SUMPRODUCT(--({O4;O7;O10;O13;O16}=O13))=2, IFERROR(IFS(O13=$O4,IF(VALUE(LEFT(J4,FIND("-",J4)-1))<VALUE(RIGHT(J4,LEN(J4)-FIND("-",J4))),1,0),O13=$O7,IF(VALUE(LEFT(J7,FIND("-",J7)-1))<VALUE(RIGHT(J7,LEN(J7)-FIND("-",J7))),1,0),O13=$O10,IF(VALUE(LEFT(J10,FIND("-",J10)-1))<VALUE(RIGHT(J10,LEN(J10)-FIND("-",J10))),1,0),O13=$O16,IF(VALUE(LEFT(K13,FIND("-",K13)-1))>VALUE(RIGHT(K13,LEN(K13)-FIND("-",K13))),1,0)),""),"")} | R13: {=O13+IF(SUMPRODUCT(--({O4;O7;O10;O13;O16}=O13))=2,Q13*0.1,IF(SUMPRODUCT(--({O4;O7;O10;O13;O16}=O13))>=3,P14*0.01,0))} -> 1 | S13: {=_xlfn.RANK.EQ(R13, {R4;R7;R10;R13;R16}) & "位"} -> 4位
P14: =IFERROR( SUMPRODUCT(IFERROR(--(LEFT(G13:K13,FIND("-",G13:K13)-1)),0)) / (SUMPRODUCT(IFERROR(--(LEFT(G13:K13,FIND("-",G13:K13)-1)),0)) + SUMPRODUCT(IFERROR(--(RIGHT(G13:K13,LEN(G13:K13)-FIND("-",G13:K13))),0))) , 0) -> 0.25
C15: =IFERROR(VLOOKUP(B13&"-"&2,'リスト'!$B:$D,2,FALSE),"") -> 藤田 美和 | F15: =IFERROR(VLOOKUP(B13&"-"&2,'リスト'!$B:$D,3,FALSE),"") -> フリー
B16: 49 | C16: =IFERROR(VLOOKUP(B16&"-"&1,'リスト'!$B:$D,2,FALSE),"") -> 清水 貴志 | F16: =IFERROR(VLOOKUP(B16&"-"&1,'リスト'!$B:$D,3,FALSE),"") -> フリー | G16: =IFERROR(MID(K4, FIND("-", K4) + 1, 100) & "-" & LEFT(K4, FIND("-", K4) - 1), "") -> 0-6 | H16: =IFERROR(MID(K7, FIND("-", K7) + 1, 100) & "-" & LEFT(K7, FIND("-", K7) - 1), "") -> 0-6 | I16: =IFERROR(MID(K10, FIND("-", K10) + 1, 100) & "-" & LEFT(K10, FIND("-", K10) - 1), "") -> 0-6 | J16: =IFERROR(MID(K13, FIND("-", K13) + 1, 100) & "-" & LEFT(K13, FIND("-", K13) - 1), "") -> 0-6 | K16: =IFERROR(__xludf.DUMMYFUNCTION("SPARKLINE({1,0})"),"") | L16: =IFERROR(__xludf.DUMMYFUNCTION("SUMPRODUCT(--(REGEXMATCH(TO_TEXT(G16:K16), ""-"")), IFERROR(--(LEFT(G16:K16,FIND(""-"",G16:K16)-1)>RIGHT(G16:K16,LEN(G16:K16)-FIND(""-"",G16:K16))),0)) & ""-"" & SUMPRODUCT(--(REGEXMATCH(TO_TEXT(G16:K16), ""-"")), IFERROR(--(LEFT(G16:K16,FIND(""-"",G16:K1"&"6)-1)<RIGHT(G16:K16,LEN(G16:K16)-FIND(""-"",G16:K16))),0))"),"0-4") -> 0-4 | M16: =IF(COUNTA($G$4,$H$4,$H$7,$H$10,$H$13,$I$4,$I$7,$I$10,$I$13,$J$4,$J$7,$J$10,$J$13,$K$4,$K$7,$K$10,$K$13,$G$7,$G$10,$G$13,$G$16,$H$16,$I$16,$J$16,$K$16)=25,S16,"") -> 5位 | O16: =IFERROR(VALUE(LEFT(L16,FIND("-",L16)-1)),-1) -> 0 | P16: =SUMPRODUCT(IFERROR(--(LEFT(G16:K16,FIND("-",G16:K16)-1)),0)) & "/" & (SUMPRODUCT(IFERROR(--(LEFT(G16:K16,FIND("-",G16:K16)-1)),0)) + SUMPRODUCT(IFERROR(--(RIGHT(G16:K16,LEN(G16:K16)-FIND("-",G16:K16))),0))) -> 0/24 | Q16: {=IF(SUMPRODUCT(--({O4;O7;O10;O13;O16}=O16))=2, IFERROR(IFS(O16=$O4,IF(VALUE(LEFT(K4,FIND("-",K4)-1))<VALUE(RIGHT(K4,LEN(K4)-FIND("-",K4))),1,0),O16=$O7,IF(VALUE(LEFT(K7,FIND("-",K7)-1))<VALUE(RIGHT(K7,LEN(K7)-FIND("-",K7))),1,0),O16=$O10,IF(VALUE(LEFT(K10,FIND("-",K10)-1))<VALUE(RIGHT(K10,LEN(K10)-FIND("-",K10))),1,0),O16=$O13,IF(VALUE(LEFT(K13,FIND("-",K13)-1))<VALUE(RIGHT(K13,LEN(K13)-FIND("-",K13))),1,0)),""),"")} | R16: {=O16+IF(SUMPRODUCT(--({O4;O7;O10;O13;O16}=O16))=2,Q16*0.1,IF(SUMPRODUCT(--({O4;O7;O10;O13;O16}=O16))>=3,P17*0.01,0))} -> 0 | S16: {=_xlfn.RANK.EQ(R16, {R4;R7;R10;R13;R16}) & "位"} -> 5位
P17: =IFERROR( SUMPRODUCT(IFERROR(--(LEFT(G16:K16,FIND("-",G16:K16)-1)),0)) / (SUMPRODUCT(IFERROR(--(LEFT(G16:K16,FIND("-",G16:K16)-1)),0)) + SUMPRODUCT(IFERROR(--(RIGHT(G16:K16,LEN(G16:K16)-FIND("-",G16:K16))),0))) , 0) -> 0
C18: =IFERROR(VLOOKUP(B16&"-"&2,'リスト'!$B:$D,2,FALSE),"") -> 大田 陽子 | F18: =IFERROR(VLOOKUP(B16&"-"&2,'リスト'!$B:$D,3,FALSE),"") -> たんぽぽ
B20: M | E20: リーグ | J20: =TRIM('予選'!$A$1) -> サンプル
B21: 選手名 | G21: =LEFT(C22, FIND(" ", C22 & " ") - 1) & "・" & LEFT(C24, FIND(" ", C24 & " ") - 1) -> 竹安・楠瀬 | H21: =LEFT(C25, FIND(" ", C25 & " ") - 1) & "・" & LEFT(C27, FIND(" ", C27 & " ") - 1) -> 橋本・今城 | I21: =LEFT(C28, FIND(" ", C28 & " ") - 1) & "・" & LEFT(C30, FIND(" ", C30 & " ") - 1) -> 井嶋・高木 | J21: =LEFT(C31, FIND(" ", C31 & " ") - 1) & "・" & LEFT(C33, FIND(" ", C33 & " ") - 1) -> 吉田・吉田 | K21: =LEFT(C34, FIND(" ", C34 & " ") - 1) & "・" & LEFT(C36, FIND(" ", C36 & " ") - 1) -> 遠藤・遠藤 | L21: 勝敗 | M21: 順位 | O21: 勝数 | P21: 勝率 | Q21: 直接対決 | R21: 判定 | S21: 順位
B22: 50 | C22: =IFERROR(VLOOKUP(B22&"-"&1,'リスト'!$B:$D,2,FALSE),"") -> 竹安 秀平 | F22: =IFERROR(VLOOKUP(B22&"-"&1,'リスト'!$B:$D,3,FALSE),"") -> ＲｅＦｌｅｘ | G22: =IFERROR(__xludf.DUMMYFUNCTION("SPARKLINE({1,0})"),"") | H22: 6-2 | I22: 3-6 | J22: 6-1 | K22: 6-4 | L22: =IFERROR(__xludf.DUMMYFUNCTION("SUMPRODUCT(--(REGEXMATCH(TO_TEXT(G22:K22), ""-"")), IFERROR(--(LEFT(G22:K22,FIND(""-"",G22:K22)-1)>RIGHT(G22:K22,LEN(G22:K22)-FIND(""-"",G22:K22))),0)) & ""-"" & SUMPRODUCT(--(REGEXMATCH(TO_TEXT(G22:K22), ""-"")), IFERROR(--(LEFT(G22:K22,FIND(""-"",G22:K2"&"2)-1)<RIGHT(G22:K22,LEN(G22:K22)-FIND(""-"",G22:K22))),0))"),"3-1") -> 3-1 | M22: =IF(COUNTA($G$22,$H$22,$H$25,$H$28,$H$31,$I$22,$I$25,$I$28,$I$31,$J$22,$J$25,$J$28,$J$31,$K$22,$K$25,$K$28,$K$31,$G$25,$G$28,$G$31,$G$34,$H$34,$I$34,$J$34,$K$34)=25,S22,"") -> 1位 | O22: =IFERROR(VALUE(LEFT(L22,FIND("-",L22)-1)),-1) -> 3 | P22: =SUMPRODUCT(IFERROR(--(LEFT(H22:K22,FIND("-",H22:K22)-1)),0)) & "/" & (SUMPRODUCT(IFERROR(--(LEFT(H22:K22,FIND("-",H22:K22)-1)),0)) + SUMPRODUCT(IFERROR(--(RIGHT(H22:K22,LEN(H22:K22)-FIND("-",H22:K22))),0))) -> 21/34 | Q22: {=IF(SUMPRODUCT(--({$O22;$O25;$O28;$O31;$O34}=O22))=2, IFERROR(IFS(O22=$O25,IF(VALUE(LEFT(H22,FIND("-",H22)-1))>VALUE(RIGHT(H22,LEN(H22)-FIND("-",H22))),1,0),O22=$O28,IF(VALUE(LEFT(I22,FIND("-",I22)-1))>VALUE(RIGHT(I22,LEN(I22)-FIND("-",I22))),1,0),O22=$O31,IF(VALUE(LEFT(J22,FIND("-",J22)-1))>VALUE(RIGHT(J22,LEN(J22)-FIND("-",J22))),1,0),O22=$O34,IF(VALUE(LEFT(K22,FIND("-",K22)-1))>VALUE(RIGHT(K22,LEN(K22)-FIND("-",K22))),1,0)),""),"")} -> 1 | R22: {=O22+IF(SUMPRODUCT(--({O22;O25;O28;O31;O34}=O22))=2,Q22*0.1,IF(SUMPRODUCT(--({O22;O25;O28;O31;O34}=O22))>=3,P23*0.01,0))} -> 3.1 | S22: {=_xlfn.RANK.EQ(R22, {R22;R25;R28;R31;R34}) & "位"} -> 1位
P23: =IFERROR( SUMPRODUCT(IFERROR(--(LEFT(H22:K22,FIND("-",H22:K22)-1)),0)) / (SUMPRODUCT(IFERROR(--(LEFT(H22:K22,FIND("-",H22:K22)-1)),0)) + SUMPRODUCT(IFERROR(--(RIGHT(H22:K22,LEN(H22:K22)-FIND("-",H22:K22))),0))) , 0) -> 0.61764706
C24: =IFERROR(VLOOKUP(B22&"-"&2,'リスト'!$B:$D,2,FALSE),"") -> 楠瀬 翔子 | F24: =IFERROR(VLOOKUP(B22&"-"&2,'リスト'!$B:$D,3,FALSE),"") -> アポロＴＣ
B25: 51 | C25: =IFERROR(VLOOKUP(B25&"-"&1,'リスト'!$B:$D,2,FALSE),"") -> 橋本 義斉 | F25: =IFERROR(VLOOKUP(B25&"-"&1,'リスト'!$B:$D,3,FALSE),"") -> Drop☆Shot | G25: =IFERROR(MID(H22, FIND("-", H22) + 1, 100) & "-" & LEFT(H22, FIND("-", H22) - 1), "") -> 2-6 | H25: =IFERROR(__xludf.DUMMYFUNCTION("SPARKLINE({1,0})"),"") | I25: 6-0 | J25: 6-0 | K25: 6-3 | L25: =IFERROR(__xludf.DUMMYFUNCTION("SUMPRODUCT(--(REGEXMATCH(TO_TEXT(G25:K25), ""-"")), IFERROR(--(LEFT(G25:K25,FIND(""-"",G25:K25)-1)>RIGHT(G25:K25,LEN(G25:K25)-FIND(""-"",G25:K25))),0)) & ""-"" & SUMPRODUCT(--(REGEXMATCH(TO_TEXT(G25:K25), ""-"")), IFERROR(--(LEFT(G25:K25,FIND(""-"",G25:K2"&"5)-1)<RIGHT(G25:K25,LEN(G25:K25)-FIND(""-"",G25:K25))),0))"),"3-1") -> 3-1 | M25: =IF(COUNTA($G$22,$H$22,$H$25,$H$28,$H$31,$I$22,$I$25,$I$28,$I$31,$J$22,$J$25,$J$28,$J$31,$K$22,$K$25,$K$28,$K$31,$G$25,$G$28,$G$31,$G$34,$H$34,$I$34,$J$34,$K$34)=25,S25,"") -> 2位 | O25: =IFERROR(VALUE(LEFT(L25,FIND("-",L25)-1)),-1) -> 3 | P25: =SUMPRODUCT(IFERROR(--(LEFT(G25:K25,FIND("-",G25:K25)-1)),0)) & "/" & (SUMPRODUCT(IFERROR(--(LEFT(G25:K25,FIND("-",G25:K25)-1)),0)) + SUMPRODUCT(IFERROR(--(RIGHT(G25:K25,LEN(G25:K25)-FIND("-",G25:K25))),0))) -> 20/29 | Q25: {=IF(SUMPRODUCT(--({O22;O25;O28;O31;O34}=O25))=2, IFERROR(IFS(O25=$O22,IF(VALUE(LEFT(H22,FIND("-",H22)-1))<VALUE(RIGHT(H22,LEN(H22)-FIND("-",H22))),1,0),O25=$O28,IF(VALUE(LEFT(I25,FIND("-",I25)-1))>VALUE(RIGHT(I25,LEN(I25)-FIND("-",I25))),1,0),O25=$O31,IF(VALUE(LEFT(J25,FIND("-",J25)-1))>VALUE(RIGHT(J25,LEN(J25)-FIND("-",J25))),1,0),O25=$O34,IF(VALUE(LEFT(K25,FIND("-",K25)-1))>VALUE(RIGHT(K25,LEN(K25)-FIND("-",K25))),1,0)),""),"")} -> 0 | R25: {=O25+IF(SUMPRODUCT(--({O22;O25;O28;O31;O34}=O25))=2,Q25*0.1,IF(SUMPRODUCT(--({O22;O25;O28;O31;O34}=O25))>=3,P26*0.01,0))} -> 3 | S25: {=_xlfn.RANK.EQ(R25, {R22;R25;R28;R31;R34}) & "位"} -> 2位
P26: =IFERROR( SUMPRODUCT(IFERROR(--(LEFT(G25:K25,FIND("-",G25:K25)-1)),0)) / (SUMPRODUCT(IFERROR(--(LEFT(G25:K25,FIND("-",G25:K25)-1)),0)) + SUMPRODUCT(IFERROR(--(RIGHT(G25:K25,LEN(G25:K25)-FIND("-",G25:K25))),0))) , 0) -> 0.68965517
C27: =IFERROR(VLOOKUP(B25&"-"&2,'リスト'!$B:$D,2,FALSE),"") -> 今城 由美 | F27: =IFERROR(VLOOKUP(B25&"-"&2,'リスト'!$B:$D,3,FALSE),"") -> レイリー
B28: 52 | C28: =IFERROR(VLOOKUP(B28&"-"&1,'リスト'!$B:$D,2,FALSE),"") -> 井嶋 昭二 | F28: =IFERROR(VLOOKUP(B28&"-"&1,'リスト'!$B:$D,3,FALSE),"") -> RedHotChiliPeppers | G28: =IFERROR(MID(I22, FIND("-", I22) + 1, 100) & "-" & LEFT(I22, FIND("-", I22) - 1), "") -> 6-3 | H28: =IFERROR(MID(I25, FIND("-", I25) + 1, 100) & "-" & LEFT(I25, FIND("-", I25) - 1), "") -> 0-6 | I28: =IFERROR(__xludf.DUMMYFUNCTION("SPARKLINE({1,0})"),"") | J28: 3-6 | K28: 6-0 | L28: =IFERROR(__xludf.DUMMYFUNCTION("SUMPRODUCT(--(REGEXMATCH(TO_TEXT(G28:K28), ""-"")), IFERROR(--(LEFT(G28:K28,FIND(""-"",G28:K28)-1)>RIGHT(G28:K28,LEN(G28:K28)-FIND(""-"",G28:K28))),0)) & ""-"" & SUMPRODUCT(--(REGEXMATCH(TO_TEXT(G28:K28), ""-"")), IFERROR(--(LEFT(G28:K28,FIND(""-"",G28:K2"&"8)-1)<RIGHT(G28:K28,LEN(G28:K28)-FIND(""-"",G28:K28))),0))"),"2-2") -> 2-2 | M28: =IF(COUNTA($G$22,$H$22,$H$25,$H$28,$H$31,$I$22,$I$25,$I$28,$I$31,$J$22,$J$25,$J$28,$J$31,$K$22,$K$25,$K$28,$K$31,$G$25,$G$28,$G$31,$G$34,$H$34,$I$34,$J$34,$K$34)=25,S28,"") -> 3位 | O28: =IFERROR(VALUE(LEFT(L28,FIND("-",L28)-1)),-1) -> 2 | P28: =SUMPRODUCT(IFERROR(--(LEFT(G28:K28,FIND("-",G28:K28)-1)),0)) & "/" & (SUMPRODUCT(IFERROR(--(LEFT(G28:K28,FIND("-",G28:K28)-1)),0)) + SUMPRODUCT(IFERROR(--(RIGHT(G28:K28,LEN(G28:K28)-FIND("-",G28:K28))),0))) -> 15/30 | Q28: {=IF(SUMPRODUCT(--({O22;O25;O28;O31;O34}=O28))=2, IFERROR(IFS(O28=$O22,IF(VALUE(LEFT(I22,FIND("-",I22)-1))<VALUE(RIGHT(I22,LEN(I22)-FIND("-",I22))),1,0),O28=$O25,IF(VALUE(LEFT(I25,FIND("-",I25)-1))<VALUE(RIGHT(I25,LEN(I25)-FIND("-",I25))),1,0),O28=$O31,IF(VALUE(LEFT(J28,FIND("-",J28)-1))>VALUE(RIGHT(J28,LEN(J28)-FIND("-",J28))),1,0),O28=$O34,IF(VALUE(LEFT(K28,FIND("-",K28)-1))>VALUE(RIGHT(K28,LEN(K28)-FIND("-",K28))),1,0)),""),"")} | R28: {=O28+IF(SUMPRODUCT(--({O22;O25;O28;O31;O34}=O28))=2,Q28*0.1,IF(SUMPRODUCT(--({O22;O25;O28;O31;O34}=O28))>=3,P29*0.01,0))} -> 2 | S28: {=_xlfn.RANK.EQ(R28, {R22;R25;R28;R31;R34}) & "位"} -> 3位
P29: =IFERROR( SUMPRODUCT(IFERROR(--(LEFT(G28:K28,FIND("-",G28:K28)-1)),0)) / (SUMPRODUCT(IFERROR(--(LEFT(G28:K28,FIND("-",G28:K28)-1)),0)) + SUMPRODUCT(IFERROR(--(RIGHT(G28:K28,LEN(G28:K28)-FIND("-",G28:K28))),0))) , 0) -> 0.5
C30: =IFERROR(VLOOKUP(B28&"-"&2,'リスト'!$B:$D,2,FALSE),"") -> 高木 美穂 | F30: =IFERROR(VLOOKUP(B28&"-"&2,'リスト'!$B:$D,3,FALSE),"") -> ラフ
B31: 53 | C31: =IFERROR(VLOOKUP(B31&"-"&1,'リスト'!$B:$D,2,FALSE),"") -> 吉田 拳士 | F31: =IFERROR(VLOOKUP(B31&"-"&1,'リスト'!$B:$D,3,FALSE),"") -> サニーテニス | G31: =IFERROR(MID(J22, FIND("-", J22) + 1, 100) & "-" & LEFT(J22, FIND("-", J22) - 1), "") -> 1-6 | H31: =IFERROR(MID(J25, FIND("-", J25) + 1, 100) & "-" & LEFT(J25, FIND("-", J25) - 1), "") -> 0-6 | I31: =IFERROR(MID(J28, FIND("-", J28) + 1, 100) & "-" & LEFT(J28, FIND("-", J28) - 1), "") -> 6-3 | J31: =IFERROR(__xludf.DUMMYFUNCTION("SPARKLINE({1,0})"),"") | K31: 1-6 | L31: =IFERROR(__xludf.DUMMYFUNCTION("SUMPRODUCT(--(REGEXMATCH(TO_TEXT(G31:K31), ""-"")), IFERROR(--(LEFT(G31:K31,FIND(""-"",G31:K31)-1)>RIGHT(G31:K31,LEN(G31:K31)-FIND(""-"",G31:K31))),0)) & ""-"" & SUMPRODUCT(--(REGEXMATCH(TO_TEXT(G31:K31), ""-"")), IFERROR(--(LEFT(G31:K31,FIND(""-"",G31:K3"&"1)-1)<RIGHT(G31:K31,LEN(G31:K31)-FIND(""-"",G31:K31))),0))"),"1-3") -> 1-3 | M31: =IF(COUNTA($G$22,$H$22,$H$25,$H$28,$H$31,$I$22,$I$25,$I$28,$I$31,$J$22,$J$25,$J$28,$J$31,$K$22,$K$25,$K$28,$K$31,$G$25,$G$28,$G$31,$G$34,$H$34,$I$34,$J$34,$K$34)=25,S31,"") -> 5位 | O31: =IFERROR(VALUE(LEFT(L31,FIND("-",L31)-1)),-1) -> 1 | P31: =SUMPRODUCT(IFERROR(--(LEFT(G31:K31,FIND("-",G31:K31)-1)),0)) & "/" & (SUMPRODUCT(IFERROR(--(LEFT(G31:K31,FIND("-",G31:K31)-1)),0)) + SUMPRODUCT(IFERROR(--(RIGHT(G31:K31,LEN(G31:K31)-FIND("-",G31:K31))),0))) -> 8/29 | Q31: {=IF(SUMPRODUCT(--({O22;O25;O28;O31;O34}=O31))=2, IFERROR(IFS(O31=$O22,IF(VALUE(LEFT(J22,FIND("-",J22)-1))<VALUE(RIGHT(J22,LEN(J22)-FIND("-",J22))),1,0),O31=$O25,IF(VALUE(LEFT(J25,FIND("-",J25)-1))<VALUE(RIGHT(J25,LEN(J25)-FIND("-",J25))),1,0),O31=$O28,IF(VALUE(LEFT(J28,FIND("-",J28)-1))<VALUE(RIGHT(J28,LEN(J28)-FIND("-",J28))),1,0),O31=$O34,IF(VALUE(LEFT(K31,FIND("-",K31)-1))>VALUE(RIGHT(K31,LEN(K31)-FIND("-",K31))),1,0)),""),"")} -> 0 | R31: {=O31+IF(SUMPRODUCT(--({O22;O25;O28;O31;O34}=O31))=2,Q31*0.1,IF(SUMPRODUCT(--({O22;O25;O28;O31;O34}=O31))>=3,P32*0.01,0))} -> 1 | S31: {=_xlfn.RANK.EQ(R31, {R22;R25;R28;R31;R34}) & "位"} -> 5位
P32: =IFERROR( SUMPRODUCT(IFERROR(--(LEFT(G31:K31,FIND("-",G31:K31)-1)),0)) / (SUMPRODUCT(IFERROR(--(LEFT(G31:K31,FIND("-",G31:K31)-1)),0)) + SUMPRODUCT(IFERROR(--(RIGHT(G31:K31,LEN(G31:K31)-FIND("-",G31:K31))),0))) , 0) -> 0.27586207
C33: =IFERROR(VLOOKUP(B31&"-"&2,'リスト'!$B:$D,2,FALSE),"") -> 吉田 由乃 | F33: =IFERROR(VLOOKUP(B31&"-"&2,'リスト'!$B:$D,3,FALSE),"") -> サニーテニス
B34: 54 | C34: =IFERROR(VLOOKUP(B34&"-"&1,'リスト'!$B:$D,2,FALSE),"") -> 遠藤 絢弥 | F34: =IFERROR(VLOOKUP(B34&"-"&1,'リスト'!$B:$D,3,FALSE),"") -> フリー | G34: =IFERROR(MID(K22, FIND("-", K22) + 1, 100) & "-" & LEFT(K22, FIND("-", K22) - 1), "") -> 4-6 | H34: =IFERROR(MID(K25, FIND("-", K25) + 1, 100) & "-" & LEFT(K25, FIND("-", K25) - 1), "") -> 3-6 | I34: =IFERROR(MID(K28, FIND("-", K28) + 1, 100) & "-" & LEFT(K28, FIND("-", K28) - 1), "") -> 0-6 | J34: =IFERROR(MID(K31, FIND("-", K31) + 1, 100) & "-" & LEFT(K31, FIND("-", K31) - 1), "") -> 6-1 | K34: =IFERROR(__xludf.DUMMYFUNCTION("SPARKLINE({1,0})"),"") | L34: =IFERROR(__xludf.DUMMYFUNCTION("SUMPRODUCT(--(REGEXMATCH(TO_TEXT(G34:K34), ""-"")), IFERROR(--(LEFT(G34:K34,FIND(""-"",G34:K34)-1)>RIGHT(G34:K34,LEN(G34:K34)-FIND(""-"",G34:K34))),0)) & ""-"" & SUMPRODUCT(--(REGEXMATCH(TO_TEXT(G34:K34), ""-"")), IFERROR(--(LEFT(G34:K34,FIND(""-"",G34:K3"&"4)-1)<RIGHT(G34:K34,LEN(G34:K34)-FIND(""-"",G34:K34))),0))"),"1-3") -> 1-3 | M34: =IF(COUNTA($G$22,$H$22,$H$25,$H$28,$H$31,$I$22,$I$25,$I$28,$I$31,$J$22,$J$25,$J$28,$J$31,$K$22,$K$25,$K$28,$K$31,$G$25,$G$28,$G$31,$G$34,$H$34,$I$34,$J$34,$K$34)=25,S34,"") -> 4位 | O34: =IFERROR(VALUE(LEFT(L34,FIND("-",L34)-1)),-1) -> 1 | P34: =SUMPRODUCT(IFERROR(--(LEFT(G34:K34,FIND("-",G34:K34)-1)),0)) & "/" & (SUMPRODUCT(IFERROR(--(LEFT(G34:K34,FIND("-",G34:K34)-1)),0)) + SUMPRODUCT(IFERROR(--(RIGHT(G34:K34,LEN(G34:K34)-FIND("-",G34:K34))),0))) -> 13/32 | Q34: {=IF(SUMPRODUCT(--({O22;O25;O28;O31;O34}=O34))=2, IFERROR(IFS(O34=$O22,IF(VALUE(LEFT(K22,FIND("-",K22)-1))<VALUE(RIGHT(K22,LEN(K22)-FIND("-",K22))),1,0),O34=$O25,IF(VALUE(LEFT(K25,FIND("-",K25)-1))<VALUE(RIGHT(K25,LEN(K25)-FIND("-",K25))),1,0),O34=$O28,IF(VALUE(LEFT(K28,FIND("-",K28)-1))<VALUE(RIGHT(K28,LEN(K28)-FIND("-",K28))),1,0),O34=$O31,IF(VALUE(LEFT(K31,FIND("-",K31)-1))<VALUE(RIGHT(K31,LEN(K31)-FIND("-",K31))),1,0)),""),"")} -> 1 | R34: {=O34+IF(SUMPRODUCT(--({O22;O25;O28;O31;O34}=O34))=2,Q34*0.1,IF(SUMPRODUCT(--({O22;O25;O28;O31;O34}=O34))>=3,P35*0.01,0))} -> 1.1 | S34: {=_xlfn.RANK.EQ(R34, {R22;R25;R28;R31;R34}) & "位"} -> 4位
P35: =IFERROR( SUMPRODUCT(IFERROR(--(LEFT(G34:K34,FIND("-",G34:K34)-1)),0)) / (SUMPRODUCT(IFERROR(--(LEFT(G34:K34,FIND("-",G34:K34)-1)),0)) + SUMPRODUCT(IFERROR(--(RIGHT(G34:K34,LEN(G34:K34)-FIND("-",G34:K34))),0))) , 0) -> 0.40625
C36: =IFERROR(VLOOKUP(B34&"-"&2,'リスト'!$B:$D,2,FALSE),"") -> 遠藤 夏希 | F36: =IFERROR(VLOOKUP(B34&"-"&2,'リスト'!$B:$D,3,FALSE),"") -> 湖山池ＴＣ

Sheet 対戦順
A1: トーナメント | C1: A | F1: B | I1: 試合結果 | L1: 複数選択
A2: 種目 | B2: 回線 | C2: 番号 | D2: 名前 | F2: 番号 | G2: 名前 | I2: A | J2: B | K2: タイブレ | L2: FALSE
A3: ='順位別トーナメント'!$B$2 -> 1位トーナメント | B3: 1回線 | C3: ='順位別トーナメント'!B6 -> 5 | D3: =IFERROR(VLOOKUP(C3&"-"&1,'リスト'!$B:$D,2,FALSE),"") -> 常村 和仁 | E3: =IFERROR(VLOOKUP(C3&"-"&2,'リスト'!$B:$D,2,FALSE),"") -> 前田 良枝 | F3: ='順位別トーナメント'!B8 -> 9 | G3: =IFERROR(VLOOKUP(F3&"-"&1,'リスト'!$B:$D,2,FALSE),"") -> 近藤 哲生 | H3: =IFERROR(VLOOKUP(F3&"-"&2,'リスト'!$B:$D,2,FALSE),"") -> 前田 陽子 | I3: 6 | J3: 3 | L3: FALSE
A4: ='順位別トーナメント'!$B$2 -> 1位トーナメント | B4: 1回線 | C4: ='順位別トーナメント'!B10 -> 13 | D4: =IFERROR(VLOOKUP(C4&"-"&1,'リスト'!$B:$D,2,FALSE),"") -> 小谷 桂介 | E4: =IFERROR(VLOOKUP(C4&"-"&2,'リスト'!$B:$D,2,FALSE),"") -> 小谷 佐知子 | F4: ='順位別トーナメント'!B12 -> 17 | G4: =IFERROR(VLOOKUP(F4&"-"&1,'リスト'!$B:$D,2,FALSE),"") -> 谷本 卓也 | H4: =IFERROR(VLOOKUP(F4&"-"&2,'リスト'!$B:$D,2,FALSE),"") -> 谷口 圭子 | I4: 3 | J4: 6 | L4: FALSE
A5: ='順位別トーナメント'!$B$2 -> 1位トーナメント | B5: 1回線 | C5: ='順位別トーナメント'!B14 -> 21 | D5: =IFERROR(VLOOKUP(C5&"-"&1,'リスト'!$B:$D,2,FALSE),"") -> 杉野 隆志 | E5: =IFERROR(VLOOKUP(C5&"-"&2,'リスト'!$B:$D,2,FALSE),"") -> 中村 公恵 | F5: ='順位別トーナメント'!B16 -> 25 | G5: =IFERROR(VLOOKUP(F5&"-"&1,'リスト'!$B:$D,2,FALSE),"") -> 米村 琢巳 | H5: =IFERROR(VLOOKUP(F5&"-"&2,'リスト'!$B:$D,2,FALSE),"") -> 佐藤 陽子 | I5: 3 | J5: 6 | L5: FALSE
